Workbook

Sheet Coverage
A1: # | B1: Resort | C1: Official site status | D1: factsheet (latest yr) | E1: wedding (latest yr) | F1: events (latest yr) | G1: destination_dining (latest yr) | H1: map (latest yr) | I1: dive_map (latest yr) | J1: spa_menu (latest yr) | K1: dining_menu (latest yr) | L1: dive_prices (latest yr) | M1: excursions (latest yr) | N1: kids (latest yr) | O1: villa_plans (latest yr) | P1: all_inclusive (latest yr) | Q1: sustainability (latest yr) | R1: calendar (latest yr) | S1: brochure (latest yr) | T1: press_kit (latest yr) | U1: other (latest yr) | V1: obsolete (latest yr) | W1: Total docs | X1: Current docs | Y1: Latest factsheet | Z1: Gaps (priority 1) | AA1: Rename notes
A2: 1 | B2: Six Senses Laamu | C2: blocked | D2: =IFERROR(IF(_xlfn.MAXIFS(Documents!$E$2:$E$3728,Documents!$A$2:$A$3728,$A2,Documents!$C$2:$C$3728,"factsheet")=0,"",_xlfn.MAXIFS(Documents!$E$2:$E$3728,Documents!$A$2:$A$3728,$A2,Documents!$C$2:$C$3728,"factsheet")),"") | E2: =IFERROR(IF(_xlfn.MAXIFS(Documents!$E$2:$E$3728,Documents!$A$2:$A$3728,$A2,Documents!$C$2:$C$3728,"wedding")=0,"",_xlfn.MAXIFS(Documents!$E$2:$E$3728,Documents!$A$2:$A$3728,$A2,Documents!$C$2:$C$3728,"wedding")),"") | F2: =IFERROR(IF(_xlfn.MAXIFS(Documents!$E$2:$E$3728,Documents!$A$2:$A$3728,$A2,Documents!$C$2:$C$3728,"events")=0,"",_xlfn.MAXIFS(Documents!$E$2:$E$3728,Documents!$A$2:$A$3728,$A2,Documents!$C$2:$C$3728,"events")),"") | G2: =IFERROR(IF(_xlfn.MAXIFS(Documents!$E$2:$E$3728,Documents!$A$2:$A$3728,$A2,Documents!$C$2:$C$3728,"destination_dining")=0,"",_xlfn.MAXIFS(Documents!$E$2:$E$3728,Documents!$A$2:$A$3728,$A2,Documents!$C$2:$C$3728,"destination_dining")),"") | H2: =IFERROR(IF(_xlfn.MAXIFS(Documents!$E$2:$E$3728,Documents!$A$2:$A$3728,$A2,Documents!$C$2:$C$3728,"map")=0,"",_xlfn.MAXIFS(Documents!$E$2:$E$3728,Documents!$A$2:$A$3728,$A2,Documents!$C$2:$C$3728,"map")),"") | I2: =IFERROR(IF(_xlfn.MAXIFS(Documents!$E$2:$E$3728,Documents!$A$2:$A$3728,$A2,Documents!$C$2:$C$3728,"dive_map")=0,"",_xlfn.MAXIFS(Documents!$E$2:$E$3728,Documents!$A$2:$A$3728,$A2,Documents!$C$2:$C$3728,"dive_map")),"") | J2: =IFERROR(IF(_xlfn.MAXIFS(Documents!$E$2:$E$3728,Documents!$A$2:$A$3728,$A2,Documents!$C$2:$C$3728,"spa_menu")=0,"",_xlfn.MAXIFS(Documents!$E$2:$E$3728,Documents!$A$2:$A$3728,$A2,Documents!$C$2:$C$3728,"spa_menu")),"") | K2: =IFERROR(IF(_xlfn.MAXIFS(Documents!$E$2:$E$3728,Documents!$A$2:$A$3728,$A2,Documents!$C$2:$C$3728,"dining_menu")=0,"",_xlfn.MAXIFS(Documents!$E$2:$E$3728,Documents!$A$2:$A$3728,$A2,Documents!$C$2:$C$3728,"dining_menu")),"") | L2: =IFERROR(IF(_xlfn.MAXIFS(Documents!$E$2:$E$3728,Documents!$A$2:$A$3728,$A2,Documents!$C$2:$C$3728,"dive_prices")=0,"",_xlfn.MAXIFS(Documents!$E$2:$E$3728,Documents!$A$2:$A$3728,$A2,Documents!$C$2:$C$3728,"dive_prices")),"") | M2: =IFERROR(IF(_xlfn.MAXIFS(Documents!$E$2:$E$3728,Documents!$A$2:$A$3728,$A2,Documents!$C$2:$C$3728,"excursions")=0,"",_xlfn.MAXIFS(Documents!$E$2:$E$3728,Documents!$A$2:$A$3728,$A2,Documents!$C$2:$C$3728,"excursions")),"") | N2: =IFERROR(IF(_xlfn.MAXIFS(Documents!$E$2:$E$3728,Documents!$A$2:$A$3728,$A2,Documents!$C$2:$C$3728,"kids")=0,"",_xlfn.MAXIFS(Documents!$E$2:$E$3728,Documents!$A$2:$A$3728,$A2,Documents!$C$2:$C$3728,"kids")),"") | O2: =IFERROR(IF(_xlfn.MAXIFS(Documents!$E$2:$E$3728,Documents!$A$2:$A$3728,$A2,Documents!$C$2:$C$3728,"villa_plans")=0,"",_xlfn.MAXIFS(Documents!$E$2:$E$3728,Documents!$A$2:$A$3728,$A2,Documents!$C$2:$C$3728,"villa_plans")),"") | P2: =IFERROR(IF(_xlfn.MAXIFS(Documents!$E$2:$E$3728,Documents!$A$2:$A$3728,$A2,Documents!$C$2:$C$3728,"all_inclusive")=0,"",_xlfn.MAXIFS(Documents!$E$2:$E$3728,Documents!$A$2:$A$3728,$A2,Documents!$C$2:$C$3728,"all_inclusive")),"") | Q2: =IFERROR(IF(_xlfn.MAXIFS(Documents!$E$2:$E$3728,Documents!$A$2:$A$3728,$A2,Documents!$C$2:$C$3728,"sustainability")=0,"",_xlfn.MAXIFS(Documents!$E$2:$E$3728,Documents!$A$2:$A$3728,$A2,Documents!$C$2:$C$3728,"sustainability")),"") | R2: =IFERROR(IF(_xlfn.MAXIFS(Documents!$E$2:$E$3728,Documents!$A$2:$A$3728,$A2,Documents!$C$2:$C$3728,"calendar")=0,"",_xlfn.MAXIFS(Documents!$E$2:$E$3728,Documents!$A$2:$A$3728,$A2,Documents!$C$2:$C$3728,"calendar")),"") | S2: =IFERROR(IF(_xlfn.MAXIFS(Documents!$E$2:$E$3728,Documents!$A$2:$A$3728,$A2,Documents!$C$2:$C$3728,"brochure")=0,"",_xlfn.MAXIFS(Documents!$E$2:$E$3728,Documents!$A$2:$A$3728,$A2,Documents!$C$2:$C$3728,"brochure")),"") | T2: =IFERROR(IF(_xlfn.MAXIFS(Documents!$E$2:$E$3728,Documents!$A$2:$A$3728,$A2,Documents!$C$2:$C$3728,"press_kit")=0,"",_xlfn.MAXIFS(Documents!$E$2:$E$3728,Documents!$A$2:$A$3728,$A2,Documents!$C$2:$C$3728,"press_kit")),"") | U2: =IFERROR(IF(_xlfn.MAXIFS(Documents!$E$2:$E$3728,Documents!$A$2:$A$3728,$A2,Documents!$C$2:$C$3728,"other")=0,"",_xlfn.MAXIFS(Documents!$E$2:$E$3728,Documents!$A$2:$A$3728,$A2,Documents!$C$2:$C$3728,"other")),"") | V2: =IFERROR(IF(_xlfn.MAXIFS(Documents!$E$2:$E$3728,Documents!$A$2:$A$3728,$A2,Documents!$C$2:$C$3728,"obsolete")=0,"",_xlfn.MAXIFS(Documents!$E$2:$E$3728,Documents!$A$2:$A$3728,$A2,Documents!$C$2:$C$3728,"obsolete")),"") | W2: =COUNTIFS(Documents!$A$2:$A$3728,$A2) | X2: =COUNTIFS(Documents!$A$2:$A$3728,$A2,Documents!$R$2:$R$3728,"current") | Z2: factsheet, wedding, events
A3: 2 | B3: Filitheyo Island Resort | C3: blocked-partial | D3: =IFERROR(IF(_xlfn.MAXIFS(Documents!$E$2:$E$3728,Documents!$A$2:$A$3728,$A3,Documents!$C$2:$C$3728,"factsheet")=0,"",_xlfn.MAXIFS(Documents!$E$2:$E$3728,Documents!$A$2:$A$3728,$A3,Documents!$C$2:$C$3728,"factsheet")),"") | E3: =IFERROR(IF(_xlfn.MAXIFS(Documents!$E$2:$E$3728,Documents!$A$2:$A$3728,$A3,Documents!$C$2:$C$3728,"wedding")=0,"",_xlfn.MAXIFS(Documents!$E$2:$E$3728,Documents!$A$2:$A$3728,$A3,Documents!$C$2:$C$3728,"wedding")),"") | F3: =IFERROR(IF(_xlfn.MAXIFS(Documents!$E$2:$E$3728,Documents!$A$2:$A$3728,$A3,Documents!$C$2:$C$3728,"events")=0,"",_xlfn.MAXIFS(Documents!$E$2:$E$3728,Documents!$A$2:$A$3728,$A3,Documents!$C$2:$C$3728,"events")),"") | G3: =IFERROR(IF(_xlfn.MAXIFS(Documents!$E$2:$E$3728,Documents!$A$2:$A$3728,$A3,Documents!$C$2:$C$3728,"destination_dining")=0,"",_xlfn.MAXIFS(Documents!$E$2:$E$3728,Documents!$A$2:$A$3728,$A3,Documents!$C$2:$C$3728,"destination_dining")),"") | H3: =IFERROR(IF(_xlfn.MAXIFS(Documents!$E$2:$E$3728,Documents!$A$2:$A$3728,$A3,Documents!$C$2:$C$3728,"map")=0,"",_xlfn.MAXIFS(Documents!$E$2:$E$3728,Documents!$A$2:$A$3728,$A3,Documents!$C$2:$C$3728,"map")),"") | I3: =IFERROR(IF(_xlfn.MAXIFS(Documents!$E$2:$E$3728,Documents!$A$2:$A$3728,$A3,Documents!$C$2:$C$3728,"dive_map")=0,"",_xlfn.MAXIFS(Documents!$E$2:$E$3728,Documents!$A$2:$A$3728,$A3,Documents!$C$2:$C$3728,"dive_map")),"") | J3: =IFERROR(IF(_xlfn.MAXIFS(Documents!$E$2:$E$3728,Documents!$A$2:$A$3728,$A3,Documents!$C$2:$C$3728,"spa_menu")=0,"",_xlfn.MAXIFS(Documents!$E$2:$E$3728,Documents!$A$2:$A$3728,$A3,Documents!$C$2:$C$3728,"spa_menu")),"") | K3: =IFERROR(IF(_xlfn.MAXIFS(Documents!$E$2:$E$3728,Documents!$A$2:$A$3728,$A3,Documents!$C$2:$C$3728,"dining_menu")=0,"",_xlfn.MAXIFS(Documents!$E$2:$E$3728,Documents!$A$2:$A$3728,$A3,Documents!$C$2:$C$3728,"dining_menu")),"") | L3: =IFERROR(IF(_xlfn.MAXIFS(Documents!$E$2:$E$3728,Documents!$A$2:$A$3728,$A3,Documents!$C$2:$C$3728,"dive_prices")=0,"",_xlfn.MAXIFS(Documents!$E$2:$E$3728,Documents!$A$2:$A$3728,$A3,Documents!$C$2:$C$3728,"dive_prices")),"") | M3: =IFERROR(IF(_xlfn.MAXIFS(Documents!$E$2:$E$3728,Documents!$A$2:$A$3728,$A3,Documents!$C$2:$C$3728,"excursions")=0,"",_xlfn.MAXIFS(Documents!$E$2:$E$3728,Documents!$A$2:$A$3728,$A3,Documents!$C$2:$C$3728,"excursions")),"") | N3: =IFERROR(IF(_xlfn.MAXIFS(Documents!$E$2:$E$3728,Documents!$A$2:$A$3728,$A3,Documents!$C$2:$C$3728,"kids")=0,"",_xlfn.MAXIFS(Documents!$E$2:$E$3728,Documents!$A$2:$A$3728,$A3,Documents!$C$2:$C$3728,"kids")),"") | O3: =IFERROR(IF(_xlfn.MAXIFS(Documents!$E$2:$E$3728,Documents!$A$2:$A$3728,$A3,Documents!$C$2:$C$3728,"villa_plans")=0,"",_xlfn.MAXIFS(Documents!$E$2:$E$3728,Documents!$A$2:$A$3728,$A3,Documents!$C$2:$C$3728,"villa_plans")),"") | P3: =IFERROR(IF(_xlfn.MAXIFS(Documents!$E$2:$E$3728,Documents!$A$2:$A$3728,$A3,Documents!$C$2:$C$3728,"all_inclusive")=0,"",_xlfn.MAXIFS(Documents!$E$2:$E$3728,Documents!$A$2:$A$3728,$A3,Documents!$C$2:$C$3728,"all_inclusive")),"") | Q3: =IFERROR(IF(_xlfn.MAXIFS(Documents!$E$2:$E$3728,Documents!$A$2:$A$3728,$A3,Documents!$C$2:$C$3728,"sustainability")=0,"",_xlfn.MAXIFS(Documents!$E$2:$E$3728,Documents!$A$2:$A$3728,$A3,Documents!$C$2:$C$3728,"sustainability")),"") | R3: =IFERROR(IF(_xlfn.MAXIFS(Documents!$E$2:$E$3728,Documents!$A$2:$A$3728,$A3,Documents!$C$2:$C$3728,"calendar")=0,"",_xlfn.MAXIFS(Documents!$E$2:$E$3728,Documents!$A$2:$A$3728,$A3,Documents!$C$2:$C$3728,"calendar")),"") | S3: =IFERROR(IF(_xlfn.MAXIFS(Documents!$E$2:$E$3728,Documents!$A$2:$A$3728,$A3,Documents!$C$2:$C$3728,"brochure")=0,"",_xlfn.MAXIFS(Documents!$E$2:$E$3728,Documents!$A$2:$A$3728,$A3,Documents!$C$2:$C$3728,"brochure")),"") | T3: =IFERROR(IF(_xlfn.MAXIFS(Documents!$E$2:$E$3728,Documents!$A$2:$A$3728,$A3,Documents!$C$2:$C$3728,"press_kit")=0,"",_xlfn.MAXIFS(Documents!$E$2:$E$3728,Documents!$A$2:$A$3728,$A3,Documents!$C$2:$C$3728,"press_kit")),"") | U3: =IFERROR(IF(_xlfn.MAXIFS(Documents!$E$2:$E$3728,Documents!$A$2:$A$3728,$A3,Documents!$C$2:$C$3728,"other")=0,"",_xlfn.MAXIFS(Documents!$E$2:$E$3728,Documents!$A$2:$A$3728,$A3,Documents!$C$2:$C$3728,"other")),"") | V3: =IFERROR(IF(_xlfn.MAXIFS(Documents!$E$2:$E$3728,Documents!$A$2:$A$3728,$A3,Documents!$C$2:$C$3728,"obsolete")=0,"",_xlfn.MAXIFS(Documents!$E$2:$E$3728,Documents!$A$2:$A$3728,$A3,Documents!$C$2:$C$3728,"obsolete")),"") | W3: =COUNTIFS(Documents!$A$2:$A$3728,$A3) | X3: =COUNTIFS(Documents!$A$2:$A$3728,$A3,Documents!$R$2:$R$3728,"current") | Z3: factsheet, wedding, events
A4: 3 | B4: Adaaran Select Hudhuranfushi | C4: ok | D4: =IFERROR(IF(_xlfn.MAXIFS(Documents!$E$2:$E$3728,Documents!$A$2:$A$3728,$A4,Documents!$C$2:$C$3728,"factsheet")=0,"",_xlfn.MAXIFS(Documents!$E$2:$E$3728,Documents!$A$2:$A$3728,$A4,Documents!$C$2:$C$3728,"factsheet")),"") | E4: =IFERROR(IF(_xlfn.MAXIFS(Documents!$E$2:$E$3728,Documents!$A$2:$A$3728,$A4,Documents!$C$2:$C$3728,"wedding")=0,"",_xlfn.MAXIFS(Documents!$E$2:$E$3728,Documents!$A$2:$A$3728,$A4,Documents!$C$2:$C$3728,"wedding")),"") | F4: =IFERROR(IF(_xlfn.MAXIFS(Documents!$E$2:$E$3728,Documents!$A$2:$A$3728,$A4,Documents!$C$2:$C$3728,"events")=0,"",_xlfn.MAXIFS(Documents!$E$2:$E$3728,Documents!$A$2:$A$3728,$A4,Documents!$C$2:$C$3728,"events")),"") | G4: =IFERROR(IF(_xlfn.MAXIFS(Documents!$E$2:$E$3728,Documents!$A$2:$A$3728,$A4,Documents!$C$2:$C$3728,"destination_dining")=0,"",_xlfn.MAXIFS(Documents!$E$2:$E$3728,Documents!$A$2:$A$3728,$A4,Documents!$C$2:$C$3728,"destination_dining")),"") | H4: =IFERROR(IF(_xlfn.MAXIFS(Documents!$E$2:$E$3728,Documents!$A$2:$A$3728,$A4,Documents!$C$2:$C$3728,"map")=0,"",_xlfn.MAXIFS(Documents!$E$2:$E$3728,Documents!$A$2:$A$3728,$A4,Documents!$C$2:$C$3728,"map")),"") | I4: =IFERROR(IF(_xlfn.MAXIFS(Documents!$E$2:$E$3728,Documents!$A$2:$A$3728,$A4,Documents!$C$2:$C$3728,"dive_map")=0,"",_xlfn.MAXIFS(Documents!$E$2:$E$3728,Documents!$A$2:$A$3728,$A4,Documents!$C$2:$C$3728,"dive_map")),"") | J4: =IFERROR(IF(_xlfn.MAXIFS(Documents!$E$2:$E$3728,Documents!$A$2:$A$3728,$A4,Documents!$C$2:$C$3728,"spa_menu")=0,"",_xlfn.MAXIFS(Documents!$E$2:$E$3728,Documents!$A$2:$A$3728,$A4,Documents!$C$2:$C$3728,"spa_menu")),"") | K4: =IFERROR(IF(_xlfn.MAXIFS(Documents!$E$2:$E$3728,Documents!$A$2:$A$3728,$A4,Documents!$C$2:$C$3728,"dining_menu")=0,"",_xlfn.MAXIFS(Documents!$E$2:$E$3728,Documents!$A$2:$A$3728,$A4,Documents!$C$2:$C$3728,"dining_menu")),"") | L4: =IFERROR(IF(_xlfn.MAXIFS(Documents!$E$2:$E$3728,Documents!$A$2:$A$3728,$A4,Documents!$C$2:$C$3728,"dive_prices")=0,"",_xlfn.MAXIFS(Documents!$E$2:$E$3728,Documents!$A$2:$A$3728,$A4,Documents!$C$2:$C$3728,"dive_prices")),"") | M4: =IFERROR(IF(_xlfn.MAXIFS(Documents!$E$2:$E$3728,Documents!$A$2:$A$3728,$A4,Documents!$C$2:$C$3728,"excursions")=0,"",_xlfn.MAXIFS(Documents!$E$2:$E$3728,Documents!$A$2:$A$3728,$A4,Documents!$C$2:$C$3728,"excursions")),"") | N4: =IFERROR(IF(_xlfn.MAXIFS(Documents!$E$2:$E$3728,Documents!$A$2:$A$3728,$A4,Documents!$C$2:$C$3728,"kids")=0,"",_xlfn.MAXIFS(Documents!$E$2:$E$3728,Documents!$A$2:$A$3728,$A4,Documents!$C$2:$C$3728,"kids")),"") | O4: =IFERROR(IF(_xlfn.MAXIFS(Documents!$E$2:$E$3728,Documents!$A$2:$A$3728,$A4,Documents!$C$2:$C$3728,"villa_plans")=0,"",_xlfn.MAXIFS(Documents!$E$2:$E$3728,Documents!$A$2:$A$3728,$A4,Documents!$C$2:$C$3728,"villa_plans")),"") | P4: =IFERROR(IF(_xlfn.MAXIFS(Documents!$E$2:$E$3728,Documents!$A$2:$A$3728,$A4,Documents!$C$2:$C$3728,"all_inclusive")=0,"",_xlfn.MAXIFS(Documents!$E$2:$E$3728,Documents!$A$2:$A$3728,$A4,Documents!$C$2:$C$3728,"all_inclusive")),"") | Q4: =IFERROR(IF(_xlfn.MAXIFS(Documents!$E$2:$E$3728,Documents!$A$2:$A$3728,$A4,Documents!$C$2:$C$3728,"sustainability")=0,"",_xlfn.MAXIFS(Documents!$E$2:$E$3728,Documents!$A$2:$A$3728,$A4,Documents!$C$2:$C$3728,"sustainability")),"") | R4: =IFERROR(IF(_xlfn.MAXIFS(Documents!$E$2:$E$3728,Documents!$A$2:$A$3728,$A4,Documents!$C$2:$C$3728,"calendar")=0,"",_xlfn.MAXIFS(Documents!$E$2:$E$3728,Documents!$A$2:$A$3728,$A4,Documents!$C$2:$C$3728,"calendar")),"") | S4: =IFERROR(IF(_xlfn.MAXIFS(Documents!$E$2:$E$3728,Documents!$A$2:$A$3728,$A4,Documents!$C$2:$C$3728,"brochure")=0,"",_xlfn.MAXIFS(Documents!$E$2:$E$3728,Documents!$A$2:$A$3728,$A4,Documents!$C$2:$C$3728,"brochure")),"") | T4: =IFERROR(IF(_xlfn.MAXIFS(Documents!$E$2:$E$3728,Documents!$A$2:$A$3728,$A4,Documents!$C$2:$C$3728,"press_kit")=0,"",_xlfn.MAXIFS(Documents!$E$2:$E$3728,Documents!$A$2:$A$3728,$A4,Documents!$C$2:$C$3728,"press_kit")),"") | U4: =IFERROR(IF(_xlfn.MAXIFS(Documents!$E$2:$E$3728,Documents!$A$2:$A$3728,$A4,Documents!$C$2:$C$3728,"other")=0,"",_xlfn.MAXIFS(Documents!$E$2:$E$3728,Documents!$A$2:$A$3728,$A4,Documents!$C$2:$C$3728,"other")),"") | V4: =IFERROR(IF(_xlfn.MAXIFS(Documents!$E$2:$E$3728,Documents!$A$2:$A$3728,$A4,Documents!$C$2:$C$3728,"obsolete")=0,"",_xlfn.MAXIFS(Documents!$E$2:$E$3728,Documents!$A$2:$A$3728,$A4,Documents!$C$2:$C$3728,"obsolete")),"") | W4: =COUNTIFS(Documents!$A$2:$A$3728,$A4) | X4: =COUNTIFS(Documents!$A$2:$A$3728,$A4,Documents!$R$2:$R$3728,"current") | Y4: =HYPERLINK("https://www.adaaran.com/selecthudhuranfushi/view-download/?id=menu-16","2026_document.pdf")
A5: 4 | B5: Ayada Maldives | C5: ok | D5: =IFERROR(IF(_xlfn.MAXIFS(Documents!$E$2:$E$3728,Documents!$A$2:$A$3728,$A5,Documents!$C$2:$C$3728,"factsheet")=0,"",_xlfn.MAXIFS(Documents!$E$2:$E$3728,Documents!$A$2:$A$3728,$A5,Documents!$C$2:$C$3728,"factsheet")),"") | E5: =IFERROR(IF(_xlfn.MAXIFS(Documents!$E$2:$E$3728,Documents!$A$2:$A$3728,$A5,Documents!$C$2:$C$3728,"wedding")=0,"",_xlfn.MAXIFS(Documents!$E$2:$E$3728,Documents!$A$2:$A$3728,$A5,Documents!$C$2:$C$3728,"wedding")),"") | F5: =IFERROR(IF(_xlfn.MAXIFS(Documents!$E$2:$E$3728,Documents!$A$2:$A$3728,$A5,Documents!$C$2:$C$3728,"events")=0,"",_xlfn.MAXIFS(Documents!$E$2:$E$3728,Documents!$A$2:$A$3728,$A5,Documents!$C$2:$C$3728,"events")),"") | G5: =IFERROR(IF(_xlfn.MAXIFS(Documents!$E$2:$E$3728,Documents!$A$2:$A$3728,$A5,Documents!$C$2:$C$3728,"destination_dining")=0,"",_xlfn.MAXIFS(Documents!$E$2:$E$3728,Documents!$A$2:$A$3728,$A5,Documents!$C$2:$C$3728,"destination_dining")),"") | H5: =IFERROR(IF(_xlfn.MAXIFS(Documents!$E$2:$E$3728,Documents!$A$2:$A$3728,$A5,Documents!$C$2:$C$3728,"map")=0,"",_xlfn.MAXIFS(Documents!$E$2:$E$3728,Documents!$A$2:$A$3728,$A5,Documents!$C$2:$C$3728,"map")),"") | I5: =IFERROR(IF(_xlfn.MAXIFS(Documents!$E$2:$E$3728,Documents!$A$2:$A$3728,$A5,Documents!$C$2:$C$3728,"dive_map")=0,"",_xlfn.MAXIFS(Documents!$E$2:$E$3728,Documents!$A$2:$A$3728,$A5,Documents!$C$2:$C$3728,"dive_map")),"") | J5: =IFERROR(IF(_xlfn.MAXIFS(Documents!$E$2:$E$3728,Documents!$A$2:$A$3728,$A5,Documents!$C$2:$C$3728,"spa_menu")=0,"",_xlfn.MAXIFS(Documents!$E$2:$E$3728,Documents!$A$2:$A$3728,$A5,Documents!$C$2:$C$3728,"spa_menu")),"") | K5: =IFERROR(IF(_xlfn.MAXIFS(Documents!$E$2:$E$3728,Documents!$A$2:$A$3728,$A5,Documents!$C$2:$C$3728,"dining_menu")=0,"",_xlfn.MAXIFS(Documents!$E$2:$E$3728,Documents!$A$2:$A$3728,$A5,Documents!$C$2:$C$3728,"dining_menu")),"") | L5: =IFERROR(IF(_xlfn.MAXIFS(Documents!$E$2:$E$3728,Documents!$A$2:$A$3728,$A5,Documents!$C$2:$C$3728,"dive_prices")=0,"",_xlfn.MAXIFS(Documents!$E$2:$E$3728,Documents!$A$2:$A$3728,$A5,Documents!$C$2:$C$3728,"dive_prices")),"") | M5: =IFERROR(IF(_xlfn.MAXIFS(Documents!$E$2:$E$3728,Documents!$A$2:$A$3728,$A5,Documents!$C$2:$C$3728,"excursions")=0,"",_xlfn.MAXIFS(Documents!$E$2:$E$3728,Documents!$A$2:$A$3728,$A5,Documents!$C$2:$C$3728,"excursions")),"") | N5: =IFERROR(IF(_xlfn.MAXIFS(Documents!$E$2:$E$3728,Documents!$A$2:$A$3728,$A5,Documents!$C$2:$C$3728,"kids")=0,"",_xlfn.MAXIFS(Documents!$E$2:$E$3728,Documents!$A$2:$A$3728,$A5,Documents!$C$2:$C$3728,"kids")),"") | O5: =IFERROR(IF(_xlfn.MAXIFS(Documents!$E$2:$E$3728,Documents!$A$2:$A$3728,$A5,Documents!$C$2:$C$3728,"villa_plans")=0,"",_xlfn.MAXIFS(Documents!$E$2:$E$3728,Documents!$A$2:$A$3728,$A5,Documents!$C$2:$C$3728,"villa_plans")),"") | P5: =IFERROR(IF(_xlfn.MAXIFS(Documents!$E$2:$E$3728,Documents!$A$2:$A$3728,$A5,Documents!$C$2:$C$3728,"all_inclusive")=0,"",_xlfn.MAXIFS(Documents!$E$2:$E$3728,Documents!$A$2:$A$3728,$A5,Documents!$C$2:$C$3728,"all_inclusive")),"") | Q5: =IFERROR(IF(_xlfn.MAXIFS(Documents!$E$2:$E$3728,Documents!$A$2:$A$3728,$A5,Documents!$C$2:$C$3728,"sustainability")=0,"",_xlfn.MAXIFS(Documents!$E$2:$E$3728,Documents!$A$2:$A$3728,$A5,Documents!$C$2:$C$3728,"sustainability")),"") | R5: =IFERROR(IF(_xlfn.MAXIFS(Documents!$E$2:$E$3728,Documents!$A$2:$A$3728,$A5,Documents!$C$2:$C$3728,"calendar")=0,"",_xlfn.MAXIFS(Documents!$E$2:$E$3728,Documents!$A$2:$A$3728,$A5,Documents!$C$2:$C$3728,"calendar")),"") | S5: =IFERROR(IF(_xlfn.MAXIFS(Documents!$E$2:$E$3728,Documents!$A$2:$A$3728,$A5,Documents!$C$2:$C$3728,"brochure")=0,"",_xlfn.MAXIFS(Documents!$E$2:$E$3728,Documents!$A$2:$A$3728,$A5,Documents!$C$2:$C$3728,"brochure")),"") | T5: =IFERROR(IF(_xlfn.MAXIFS(Documents!$E$2:$E$3728,Documents!$A$2:$A$3728,$A5,Documents!$C$2:$C$3728,"press_kit")=0,"",_xlfn.MAXIFS(Documents!$E$2:$E$3728,Documents!$A$2:$A$3728,$A5,Documents!$C$2:$C$3728,"press_kit")),"") | U5: =IFERROR(IF(_xlfn.MAXIFS(Documents!$E$2:$E$3728,Documents!$A$2:$A$3728,$A5,Documents!$C$2:$C$3728,"other")=0,"",_xlfn.MAXIFS(Documents!$E$2:$E$3728,Documents!$A$2:$A$3728,$A5,Documents!$C$2:$C$3728,"other")),"") | V5: =IFERROR(IF(_xlfn.MAXIFS(Documents!$E$2:$E$3728,Documents!$A$2:$A$3728,$A5,Documents!$C$2:$C$3728,"obsolete")=0,"",_xlfn.MAXIFS(Documents!$E$2:$E$3728,Documents!$A$2:$A$3728,$A5,Documents!$C$2:$C$3728,"obsolete")),"") | W5: =COUNTIFS(Documents!$A$2:$A$3728,$A5) | X5: =COUNTIFS(Documents!$A$2:$A$3728,$A5,Documents!$R$2:$R$3728,"current") | Y5: =HYPERLINK("https://www.neoscapesmaldives.com/wp-content/uploads/Ayada-Maldives-Factsheet.pdf","2024_Ayada-Maldives-Factsheet.pdf") | Z5: events
A6: 5 | B6: Bolifushi Island Resort | C6: blocked | D6: =IFERROR(IF(_xlfn.MAXIFS(Documents!$E$2:$E$3728,Documents!$A$2:$A$3728,$A6,Documents!$C$2:$C$3728,"factsheet")=0,"",_xlfn.MAXIFS(Documents!$E$2:$E$3728,Documents!$A$2:$A$3728,$A6,Documents!$C$2:$C$3728,"factsheet")),"") | E6: =IFERROR(IF(_xlfn.MAXIFS(Documents!$E$2:$E$3728,Documents!$A$2:$A$3728,$A6,Documents!$C$2:$C$3728,"wedding")=0,"",_xlfn.MAXIFS(Documents!$E$2:$E$3728,Documents!$A$2:$A$3728,$A6,Documents!$C$2:$C$3728,"wedding")),"") | F6: =IFERROR(IF(_xlfn.MAXIFS(Documents!$E$2:$E$3728,Documents!$A$2:$A$3728,$A6,Documents!$C$2:$C$3728,"events")=0,"",_xlfn.MAXIFS(Documents!$E$2:$E$3728,Documents!$A$2:$A$3728,$A6,Documents!$C$2:$C$3728,"events")),"") | G6: =IFERROR(IF(_xlfn.MAXIFS(Documents!$E$2:$E$3728,Documents!$A$2:$A$3728,$A6,Documents!$C$2:$C$3728,"destination_dining")=0,"",_xlfn.MAXIFS(Documents!$E$2:$E$3728,Documents!$A$2:$A$3728,$A6,Documents!$C$2:$C$3728,"destination_dining")),"") | H6: =IFERROR(IF(_xlfn.MAXIFS(Documents!$E$2:$E$3728,Documents!$A$2:$A$3728,$A6,Documents!$C$2:$C$3728,"map")=0,"",_xlfn.MAXIFS(Documents!$E$2:$E$3728,Documents!$A$2:$A$3728,$A6,Documents!$C$2:$C$3728,"map")),"") | I6: =IFERROR(IF(_xlfn.MAXIFS(Documents!$E$2:$E$3728,Documents!$A$2:$A$3728,$A6,Documents!$C$2:$C$3728,"dive_map")=0,"",_xlfn.MAXIFS(Documents!$E$2:$E$3728,Documents!$A$2:$A$3728,$A6,Documents!$C$2:$C$3728,"dive_map")),"") | J6: =IFERROR(IF(_xlfn.MAXIFS(Documents!$E$2:$E$3728,Documents!$A$2:$A$3728,$A6,Documents!$C$2:$C$3728,"spa_menu")=0,"",_xlfn.MAXIFS(Documents!$E$2:$E$3728,Documents!$A$2:$A$3728,$A6,Documents!$C$2:$C$3728,"spa_menu")),"") | K6: =IFERROR(IF(_xlfn.MAXIFS(Documents!$E$2:$E$3728,Documents!$A$2:$A$3728,$A6,Documents!$C$2:$C$3728,"dining_menu")=0,"",_xlfn.MAXIFS(Documents!$E$2:$E$3728,Documents!$A$2:$A$3728,$A6,Documents!$C$2:$C$3728,"dining_menu")),"") | L6: =IFERROR(IF(_xlfn.MAXIFS(Documents!$E$2:$E$3728,Documents!$A$2:$A$3728,$A6,Documents!$C$2:$C$3728,"dive_prices")=0,"",_xlfn.MAXIFS(Documents!$E$2:$E$3728,Documents!$A$2:$A$3728,$A6,Documents!$C$2:$C$3728,"dive_prices")),"") | M6: =IFERROR(IF(_xlfn.MAXIFS(Documents!$E$2:$E$3728,Documents!$A$2:$A$3728,$A6,Documents!$C$2:$C$3728,"excursions")=0,"",_xlfn.MAXIFS(Documents!$E$2:$E$3728,Documents!$A$2:$A$3728,$A6,Documents!$C$2:$C$3728,"excursions")),"") | N6: =IFERROR(IF(_xlfn.MAXIFS(Documents!$E$2:$E$3728,Documents!$A$2:$A$3728,$A6,Documents!$C$2:$C$3728,"kids")=0,"",_xlfn.MAXIFS(Documents!$E$2:$E$3728,Documents!$A$2:$A$3728,$A6,Documents!$C$2:$C$3728,"kids")),"") | O6: =IFERROR(IF(_xlfn.MAXIFS(Documents!$E$2:$E$3728,Documents!$A$2:$A$3728,$A6,Documents!$C$2:$C$3728,"villa_plans")=0,"",_xlfn.MAXIFS(Documents!$E$2:$E$3728,Documents!$A$2:$A$3728,$A6,Documents!$C$2:$C$3728,"villa_plans")),"") | P6: =IFERROR(IF(_xlfn.MAXIFS(Documents!$E$2:$E$3728,Documents!$A$2:$A$3728,$A6,Documents!$C$2:$C$3728,"all_inclusive")=0,"",_xlfn.MAXIFS(Documents!$E$2:$E$3728,Documents!$A$2:$A$3728,$A6,Documents!$C$2:$C$3728,"all_inclusive")),"") | Q6: =IFERROR(IF(_xlfn.MAXIFS(Documents!$E$2:$E$3728,Documents!$A$2:$A$3728,$A6,Documents!$C$2:$C$3728,"sustainability")=0,"",_xlfn.MAXIFS(Documents!$E$2:$E$3728,Documents!$A$2:$A$3728,$A6,Documents!$C$2:$C$3728,"sustainability")),"") | R6: =IFERROR(IF(_xlfn.MAXIFS(Documents!$E$2:$E$3728,Documents!$A$2:$A$3728,$A6,Documents!$C$2:$C$3728,"calendar")=0,"",_xlfn.MAXIFS(Documents!$E$2:$E$3728,Documents!$A$2:$A$3728,$A6,Documents!$C$2:$C$3728,"calendar")),"") | S6: =IFERROR(IF(_xlfn.MAXIFS(Documents!$E$2:$E$3728,Documents!$A$2:$A$3728,$A6,Documents!$C$2:$C$3728,"brochure")=0,"",_xlfn.MAXIFS(Documents!$E$2:$E$3728,Documents!$A$2:$A$3728,$A6,Documents!$C$2:$C$3728,"brochure")),"") | T6: =IFERROR(IF(_xlfn.MAXIFS(Documents!$E$2:$E$3728,Documents!$A$2:$A$3728,$A6,Documents!$C$2:$C$3728,"press_kit")=0,"",_xlfn.MAXIFS(Documents!$E$2:$E$3728,Documents!$A$2:$A$3728,$A6,Documents!$C$2:$C$3728,"press_kit")),"") | U6: =IFERROR(IF(_xlfn.MAXIFS(Documents!$E$2:$E$3728,Documents!$A$2:$A$3728,$A6,Documents!$C$2:$C$3728,"other")=0,"",_xlfn.MAXIFS(Documents!$E$2:$E$3728,Documents!$A$2:$A$3728,$A6,Documents!$C$2:$C$3728,"other")),"") | V6: =IFERROR(IF(_xlfn.MAXIFS(Documents!$E$2:$E$3728,Documents!$A$2:$A$3728,$A6,Documents!$C$2:$C$3728,"obsolete")=0,"",_xlfn.MAXIFS(Documents!$E$2:$E$3728,Documents!$A$2:$A$3728,$A6,Documents!$C$2:$C$3728,"obsolete")),"") | W6: =COUNTIFS(Documents!$A$2:$A$3728,$A6) | X6: =COUNTIFS(Documents!$A$2:$A$3728,$A6,Documents!$R$2:$R$3728,"current") | Y6: =HYPERLINK("https://www.neoscapesmaldives.com/wp-content/uploads/OZEN-RESERVE-BOLIFUSHI-Fact-Sheet.pdf","2023_OZEN-RESERVE-BOLIFUSHI-Fact-Sheet.p") | Z6: wedding, events | AA6: OZEN Reserve Bolifushi (confirm)
A7: 6 | B7: Joali Being Bodufushi | C7: unreachable | D7: =IFERROR(IF(_xlfn.MAXIFS(Documents!$E$2:$E$3728,Documents!$A$2:$A$3728,$A7,Documents!$C$2:$C$3728,"factsheet")=0,"",_xlfn.MAXIFS(Documents!$E$2:$E$3728,Documents!$A$2:$A$3728,$A7,Documents!$C$2:$C$3728,"factsheet")),"") | E7: =IFERROR(IF(_xlfn.MAXIFS(Documents!$E$2:$E$3728,Documents!$A$2:$A$3728,$A7,Documents!$C$2:$C$3728,"wedding")=0,"",_xlfn.MAXIFS(Documents!$E$2:$E$3728,Documents!$A$2:$A$3728,$A7,Documents!$C$2:$C$3728,"wedding")),"") | F7: =IFERROR(IF(_xlfn.MAXIFS(Documents!$E$2:$E$3728,Documents!$A$2:$A$3728,$A7,Documents!$C$2:$C$3728,"events")=0,"",_xlfn.MAXIFS(Documents!$E$2:$E$3728,Documents!$A$2:$A$3728,$A7,Documents!$C$2:$C$3728,"events")),"") | G7: =IFERROR(IF(_xlfn.MAXIFS(Documents!$E$2:$E$3728,Documents!$A$2:$A$3728,$A7,Documents!$C$2:$C$3728,"destination_dining")=0,"",_xlfn.MAXIFS(Documents!$E$2:$E$3728,Documents!$A$2:$A$3728,$A7,Documents!$C$2:$C$3728,"destination_dining")),"") | H7: =IFERROR(IF(_xlfn.MAXIFS(Documents!$E$2:$E$3728,Documents!$A$2:$A$3728,$A7,Documents!$C$2:$C$3728,"map")=0,"",_xlfn.MAXIFS(Documents!$E$2:$E$3728,Documents!$A$2:$A$3728,$A7,Documents!$C$2:$C$3728,"map")),"") | I7: =IFERROR(IF(_xlfn.MAXIFS(Documents!$E$2:$E$3728,Documents!$A$2:$A$3728,$A7,Documents!$C$2:$C$3728,"dive_map")=0,"",_xlfn.MAXIFS(Documents!$E$2:$E$3728,Documents!$A$2:$A$3728,$A7,Documents!$C$2:$C$3728,"dive_map")),"") | J7: =IFERROR(IF(_xlfn.MAXIFS(Documents!$E$2:$E$3728,Documents!$A$2:$A$3728,$A7,Documents!$C$2:$C$3728,"spa_menu")=0,"",_xlfn.MAXIFS(Documents!$E$2:$E$3728,Documents!$A$2:$A$3728,$A7,Documents!$C$2:$C$3728,"spa_menu")),"") | K7: =IFERROR(IF(_xlfn.MAXIFS(Documents!$E$2:$E$3728,Documents!$A$2:$A$3728,$A7,Documents!$C$2:$C$3728,"dining_menu")=0,"",_xlfn.MAXIFS(Documents!$E$2:$E$3728,Documents!$A$2:$A$3728,$A7,Documents!$C$2:$C$3728,"dining_menu")),"") | L7: =IFERROR(IF(_xlfn.MAXIFS(Documents!$E$2:$E$3728,Documents!$A$2:$A$3728,$A7,Documents!$C$2:$C$3728,"dive_prices")=0,"",_xlfn.MAXIFS(Documents!$E$2:$E$3728,Documents!$A$2:$A$3728,$A7,Documents!$C$2:$C$3728,"dive_prices")),"") | M7: =IFERROR(IF(_xlfn.MAXIFS(Documents!$E$2:$E$3728,Documents!$A$2:$A$3728,$A7,Documents!$C$2:$C$3728,"excursions")=0,"",_xlfn.MAXIFS(Documents!$E$2:$E$3728,Documents!$A$2:$A$3728,$A7,Documents!$C$2:$C$3728,"excursions")),"") | N7: =IFERROR(IF(_xlfn.MAXIFS(Documents!$E$2:$E$3728,Documents!$A$2:$A$3728,$A7,Documents!$C$2:$C$3728,"kids")=0,"",_xlfn.MAXIFS(Documents!$E$2:$E$3728,Documents!$A$2:$A$3728,$A7,Documents!$C$2:$C$3728,"kids")),"") | O7: =IFERROR(IF(_xlfn.MAXIFS(Documents!$E$2:$E$3728,Documents!$A$2:$A$3728,$A7,Documents!$C$2:$C$3728,"villa_plans")=0,"",_xlfn.MAXIFS(Documents!$E$2:$E$3728,Documents!$A$2:$A$3728,$A7,Documents!$C$2:$C$3728,"villa_plans")),"") | P7: =IFERROR(IF(_xlfn.MAXIFS(Documents!$E$2:$E$3728,Documents!$A$2:$A$3728,$A7,Documents!$C$2:$C$3728,"all_inclusive")=0,"",_xlfn.MAXIFS(Documents!$E$2:$E$3728,Documents!$A$2:$A$3728,$A7,Documents!$C$2:$C$3728,"all_inclusive")),"") | Q7: =IFERROR(IF(_xlfn.MAXIFS(Documents!$E$2:$E$3728,Documents!$A$2:$A$3728,$A7,Documents!$C$2:$C$3728,"sustainability")=0,"",_xlfn.MAXIFS(Documents!$E$2:$E$3728,Documents!$A$2:$A$3728,$A7,Documents!$C$2:$C$3728,"sustainability")),"") | R7: =IFERROR(IF(_xlfn.MAXIFS(Documents!$E$2:$E$3728,Documents!$A$2:$A$3728,$A7,Documents!$C$2:$C$3728,"calendar")=0,"",_xlfn.MAXIFS(Documents!$E$2:$E$3728,Documents!$A$2:$A$3728,$A7,Documents!$C$2:$C$3728,"calendar")),"") | S7: =IFERROR(IF(_xlfn.MAXIFS(Documents!$E$2:$E$3728,Documents!$A$2:$A$3728,$A7,Documents!$C$2:$C$3728,"brochure")=0,"",_xlfn.MAXIFS(Documents!$E$2:$E$3728,Documents!$A$2:$A$3728,$A7,Documents!$C$2:$C$3728,"brochure")),"") | T7: =IFERROR(IF(_xlfn.MAXIFS(Documents!$E$2:$E$3728,Documents!$A$2:$A$3728,$A7,Documents!$C$2:$C$3728,"press_kit")=0,"",_xlfn.MAXIFS(Documents!$E$2:$E$3728,Documents!$A$2:$A$3728,$A7,Documents!$C$2:$C$3728,"press_kit")),"") | U7: =IFERROR(IF(_xlfn.MAXIFS(Documents!$E$2:$E$3728,Documents!$A$2:$A$3728,$A7,Documents!$C$2:$C$3728,"other")=0,"",_xlfn.MAXIFS(Documents!$E$2:$E$3728,Documents!$A$2:$A$3728,$A7,Documents!$C$2:$C$3728,"other")),"") | V7: =IFERROR(IF(_xlfn.MAXIFS(Documents!$E$2:$E$3728,Documents!$A$2:$A$3728,$A7,Documents!$C$2:$C$3728,"obsolete")=0,"",_xlfn.MAXIFS(Documents!$E$2:$E$3728,Documents!$A$2:$A$3728,$A7,Documents!$C$2:$C$3728,"obsolete")),"") | W7: =COUNTIFS(Documents!$A$2:$A$3728,$A7) | X7: =COUNTIFS(Documents!$A$2:$A$3728,$A7,Documents!$R$2:$R$3728,"current") | Y7: =HYPERLINK("https://www.neoscapesmaldives.com/wp-content/uploads/JoaliBeing_Factsheet_V13.pdf","2023_JoaliBeing_Factsheet_V13.pdf") | Z7: wedding, events
A8: 7 | B8: Joali Muravandhoo | C8: unreachable | D8: =IFERROR(IF(_xlfn.MAXIFS(Documents!$E$2:$E$3728,Documents!$A$2:$A$3728,$A8,Documents!$C$2:$C$3728,"factsheet")=0,"",_xlfn.MAXIFS(Documents!$E$2:$E$3728,Documents!$A$2:$A$3728,$A8,Documents!$C$2:$C$3728,"factsheet")),"") | E8: =IFERROR(IF(_xlfn.MAXIFS(Documents!$E$2:$E$3728,Documents!$A$2:$A$3728,$A8,Documents!$C$2:$C$3728,"wedding")=0,"",_xlfn.MAXIFS(Documents!$E$2:$E$3728,Documents!$A$2:$A$3728,$A8,Documents!$C$2:$C$3728,"wedding")),"") | F8: =IFERROR(IF(_xlfn.MAXIFS(Documents!$E$2:$E$3728,Documents!$A$2:$A$3728,$A8,Documents!$C$2:$C$3728,"events")=0,"",_xlfn.MAXIFS(Documents!$E$2:$E$3728,Documents!$A$2:$A$3728,$A8,Documents!$C$2:$C$3728,"events")),"") | G8: =IFERROR(IF(_xlfn.MAXIFS(Documents!$E$2:$E$3728,Documents!$A$2:$A$3728,$A8,Documents!$C$2:$C$3728,"destination_dining")=0,"",_xlfn.MAXIFS(Documents!$E$2:$E$3728,Documents!$A$2:$A$3728,$A8,Documents!$C$2:$C$3728,"destination_dining")),"") | H8: =IFERROR(IF(_xlfn.MAXIFS(Documents!$E$2:$E$3728,Documents!$A$2:$A$3728,$A8,Documents!$C$2:$C$3728,"map")=0,"",_xlfn.MAXIFS(Documents!$E$2:$E$3728,Documents!$A$2:$A$3728,$A8,Documents!$C$2:$C$3728,"map")),"") | I8: =IFERROR(IF(_xlfn.MAXIFS(Documents!$E$2:$E$3728,Documents!$A$2:$A$3728,$A8,Documents!$C$2:$C$3728,"dive_map")=0,"",_xlfn.MAXIFS(Documents!$E$2:$E$3728,Documents!$A$2:$A$3728,$A8,Documents!$C$2:$C$3728,"dive_map")),"") | J8: =IFERROR(IF(_xlfn.MAXIFS(Documents!$E$2:$E$3728,Documents!$A$2:$A$3728,$A8,Documents!$C$2:$C$3728,"spa_menu")=0,"",_xlfn.MAXIFS(Documents!$E$2:$E$3728,Documents!$A$2:$A$3728,$A8,Documents!$C$2:$C$3728,"spa_menu")),"") | K8: =IFERROR(IF(_xlfn.MAXIFS(Documents!$E$2:$E$3728,Documents!$A$2:$A$3728,$A8,Documents!$C$2:$C$3728,"dining_menu")=0,"",_xlfn.MAXIFS(Documents!$E$2:$E$3728,Documents!$A$2:$A$3728,$A8,Documents!$C$2:$C$3728,"dining_menu")),"") | L8: =IFERROR(IF(_xlfn.MAXIFS(Documents!$E$2:$E$3728,Documents!$A$2:$A$3728,$A8,Documents!$C$2:$C$3728,"dive_prices")=0,"",_xlfn.MAXIFS(Documents!$E$2:$E$3728,Documents!$A$2:$A$3728,$A8,Documents!$C$2:$C$3728,"dive_prices")),"") | M8: =IFERROR(IF(_xlfn.MAXIFS(Documents!$E$2:$E$3728,Documents!$A$2:$A$3728,$A8,Documents!$C$2:$C$3728,"excursions")=0,"",_xlfn.MAXIFS(Documents!$E$2:$E$3728,Documents!$A$2:$A$3728,$A8,Documents!$C$2:$C$3728,"excursions")),"") | N8: =IFERROR(IF(_xlfn.MAXIFS(Documents!$E$2:$E$3728,Documents!$A$2:$A$3728,$A8,Documents!$C$2:$C$3728,"kids")=0,"",_xlfn.MAXIFS(Documents!$E$2:$E$3728,Documents!$A$2:$A$3728,$A8,Documents!$C$2:$C$3728,"kids")),"") | O8: =IFERROR(IF(_xlfn.MAXIFS(Documents!$E$2:$E$3728,Documents!$A$2:$A$3728,$A8,Documents!$C$2:$C$3728,"villa_plans")=0,"",_xlfn.MAXIFS(Documents!$E$2:$E$3728,Documents!$A$2:$A$3728,$A8,Documents!$C$2:$C$3728,"villa_plans")),"") | P8: =IFERROR(IF(_xlfn.MAXIFS(Documents!$E$2:$E$3728,Documents!$A$2:$A$3728,$A8,Documents!$C$2:$C$3728,"all_inclusive")=0,"",_xlfn.MAXIFS(Documents!$E$2:$E$3728,Documents!$A$2:$A$3728,$A8,Documents!$C$2:$C$3728,"all_inclusive")),"") | Q8: =IFERROR(IF(_xlfn.MAXIFS(Documents!$E$2:$E$3728,Documents!$A$2:$A$3728,$A8,Documents!$C$2:$C$3728,"sustainability")=0,"",_xlfn.MAXIFS(Documents!$E$2:$E$3728,Documents!$A$2:$A$3728,$A8,Documents!$C$2:$C$3728,"sustainability")),"") | R8: =IFERROR(IF(_xlfn.MAXIFS(Documents!$E$2:$E$3728,Documents!$A$2:$A$3728,$A8,Documents!$C$2:$C$3728,"calendar")=0,"",_xlfn.MAXIFS(Documents!$E$2:$E$3728,Documents!$A$2:$A$3728,$A8,Documents!$C$2:$C$3728,"calendar")),"") | S8: =IFERROR(IF(_xlfn.MAXIFS(Documents!$E$2:$E$3728,Documents!$A$2:$A$3728,$A8,Documents!$C$2:$C$3728,"brochure")=0,"",_xlfn.MAXIFS(Documents!$E$2:$E$3728,Documents!$A$2:$A$3728,$A8,Documents!$C$2:$C$3728,"brochure")),"") | T8: =IFERROR(IF(_xlfn.MAXIFS(Documents!$E$2:$E$3728,Documents!$A$2:$A$3728,$A8,Documents!$C$2:$C$3728,"press_kit")=0,"",_xlfn.MAXIFS(Documents!$E$2:$E$3728,Documents!$A$2:$A$3728,$A8,Documents!$C$2:$C$3728,"press_kit")),"") | U8: =IFERROR(IF(_xlfn.MAXIFS(Documents!$E$2:$E$3728,Documents!$A$2:$A$3728,$A8,Documents!$C$2:$C$3728,"other")=0,"",_xlfn.MAXIFS(Documents!$E$2:$E$3728,Documents!$A$2:$A$3728,$A8,Documents!$C$2:$C$3728,"other")),"") | V8: =IFERROR(IF(_xlfn.MAXIFS(Documents!$E$2:$E$3728,Documents!$A$2:$A$3728,$A8,Documents!$C$2:$C$3728,"obsolete")=0,"",_xlfn.MAXIFS(Documents!$E$2:$E$3728,Documents!$A$2:$A$3728,$A8,Documents!$C$2:$C$3728,"obsolete")),"") | W8: =COUNTIFS(Documents!$A$2:$A$3728,$A8) | X8: =COUNTIFS(Documents!$A$2:$A$3728,$A8,Documents!$R$2:$R$3728,"current") | Y8: =HYPERLINK("https://www.neoscapesmaldives.com/wp-content/uploads/JOALI-Maldives-Factsheet.pdf","2023_JOALI-Maldives-Factsheet.pdf") | Z8: wedding, events
A9: 8 | B9: Hilton Maldives Amingiri Resort & Spa | C9: unverified | D9: =IFERROR(IF(_xlfn.MAXIFS(Documents!$E$2:$E$3728,Documents!$A$2:$A$3728,$A9,Documents!$C$2:$C$3728,"factsheet")=0,"",_xlfn.MAXIFS(Documents!$E$2:$E$3728,Documents!$A$2:$A$3728,$A9,Documents!$C$2:$C$3728,"factsheet")),"") | E9: =IFERROR(IF(_xlfn.MAXIFS(Documents!$E$2:$E$3728,Documents!$A$2:$A$3728,$A9,Documents!$C$2:$C$3728,"wedding")=0,"",_xlfn.MAXIFS(Documents!$E$2:$E$3728,Documents!$A$2:$A$3728,$A9,Documents!$C$2:$C$3728,"wedding")),"") | F9: =IFERROR(IF(_xlfn.MAXIFS(Documents!$E$2:$E$3728,Documents!$A$2:$A$3728,$A9,Documents!$C$2:$C$3728,"events")=0,"",_xlfn.MAXIFS(Documents!$E$2:$E$3728,Documents!$A$2:$A$3728,$A9,Documents!$C$2:$C$3728,"events")),"") | G9: =IFERROR(IF(_xlfn.MAXIFS(Documents!$E$2:$E$3728,Documents!$A$2:$A$3728,$A9,Documents!$C$2:$C$3728,"destination_dining")=0,"",_xlfn.MAXIFS(Documents!$E$2:$E$3728,Documents!$A$2:$A$3728,$A9,Documents!$C$2:$C$3728,"destination_dining")),"") | H9: =IFERROR(IF(_xlfn.MAXIFS(Documents!$E$2:$E$3728,Documents!$A$2:$A$3728,$A9,Documents!$C$2:$C$3728,"map")=0,"",_xlfn.MAXIFS(Documents!$E$2:$E$3728,Documents!$A$2:$A$3728,$A9,Documents!$C$2:$C$3728,"map")),"") | I9: =IFERROR(IF(_xlfn.MAXIFS(Documents!$E$2:$E$3728,Documents!$A$2:$A$3728,$A9,Documents!$C$2:$C$3728,"dive_map")=0,"",_xlfn.MAXIFS(Documents!$E$2:$E$3728,Documents!$A$2:$A$3728,$A9,Documents!$C$2:$C$3728,"dive_map")),"") | J9: =IFERROR(IF(_xlfn.MAXIFS(Documents!$E$2:$E$3728,Documents!$A$2:$A$3728,$A9,Documents!$C$2:$C$3728,"spa_menu")=0,"",_xlfn.MAXIFS(Documents!$E$2:$E$3728,Documents!$A$2:$A$3728,$A9,Documents!$C$2:$C$3728,"spa_menu")),"") | K9: =IFERROR(IF(_xlfn.MAXIFS(Documents!$E$2:$E$3728,Documents!$A$2:$A$3728,$A9,Documents!$C$2:$C$3728,"dining_menu")=0,"",_xlfn.MAXIFS(Documents!$E$2:$E$3728,Documents!$A$2:$A$3728,$A9,Documents!$C$2:$C$3728,"dining_menu")),"") | L9: =IFERROR(IF(_xlfn.MAXIFS(Documents!$E$2:$E$3728,Documents!$A$2:$A$3728,$A9,Documents!$C$2:$C$3728,"dive_prices")=0,"",_xlfn.MAXIFS(Documents!$E$2:$E$3728,Documents!$A$2:$A$3728,$A9,Documents!$C$2:$C$3728,"dive_prices")),"") | M9: =IFERROR(IF(_xlfn.MAXIFS(Documents!$E$2:$E$3728,Documents!$A$2:$A$3728,$A9,Documents!$C$2:$C$3728,"excursions")=0,"",_xlfn.MAXIFS(Documents!$E$2:$E$3728,Documents!$A$2:$A$3728,$A9,Documents!$C$2:$C$3728,"excursions")),"") | N9: =IFERROR(IF(_xlfn.MAXIFS(Documents!$E$2:$E$3728,Documents!$A$2:$A$3728,$A9,Documents!$C$2:$C$3728,"kids")=0,"",_xlfn.MAXIFS(Documents!$E$2:$E$3728,Documents!$A$2:$A$3728,$A9,Documents!$C$2:$C$3728,"kids")),"") | O9: =IFERROR(IF(_xlfn.MAXIFS(Documents!$E$2:$E$3728,Documents!$A$2:$A$3728,$A9,Documents!$C$2:$C$3728,"villa_plans")=0,"",_xlfn.MAXIFS(Documents!$E$2:$E$3728,Documents!$A$2:$A$3728,$A9,Documents!$C$2:$C$3728,"villa_plans")),"") | P9: =IFERROR(IF(_xlfn.MAXIFS(Documents!$E$2:$E$3728,Documents!$A$2:$A$3728,$A9,Documents!$C$2:$C$3728,"all_inclusive")=0,"",_xlfn.MAXIFS(Documents!$E$2:$E$3728,Documents!$A$2:$A$3728,$A9,Documents!$C$2:$C$3728,"all_inclusive")),"") | Q9: =IFERROR(IF(_xlfn.MAXIFS(Documents!$E$2:$E$3728,Documents!$A$2:$A$3728,$A9,Documents!$C$2:$C$3728,"sustainability")=0,"",_xlfn.MAXIFS(Documents!$E$2:$E$3728,Documents!$A$2:$A$3728,$A9,Documents!$C$2:$C$3728,"sustainability")),"") | R9: =IFERROR(IF(_xlfn.MAXIFS(Documents!$E$2:$E$3728,Documents!$A$2:$A$3728,$A9,Documents!$C$2:$C$3728,"calendar")=0,"",_xlfn.MAXIFS(Documents!$E$2:$E$3728,Documents!$A$2:$A$3728,$A9,Documents!$C$2:$C$3728,"calendar")),"") | S9: =IFERROR(IF(_xlfn.MAXIFS(Documents!$E$2:$E$3728,Documents!$A$2:$A$3728,$A9,Documents!$C$2:$C$3728,"brochure")=0,"",_xlfn.MAXIFS(Documents!$E$2:$E$3728,Documents!$A$2:$A$3728,$A9,Documents!$C$2:$C$3728,"brochure")),"") | T9: =IFERROR(IF(_xlfn.MAXIFS(Documents!$E$2:$E$3728,Documents!$A$2:$A$3728,$A9,Documents!$C$2:$C$3728,"press_kit")=0,"",_xlfn.MAXIFS(Documents!$E$2:$E$3728,Documents!$A$2:$A$3728,$A9,Documents!$C$2:$C$3728,"press_kit")),"") | U9: =IFERROR(IF(_xlfn.MAXIFS(Documents!$E$2:$E$3728,Documents!$A$2:$A$3728,$A9,Documents!$C$2:$C$3728,"other")=0,"",_xlfn.MAXIFS(Documents!$E$2:$E$3728,Documents!$A$2:$A$3728,$A9,Documents!$C$2:$C$3728,"other")),"") | V9: =IFERROR(IF(_xlfn.MAXIFS(Documents!$E$2:$E$3728,Documents!$A$2:$A$3728,$A9,Documents!$C$2:$C$3728,"obsolete")=0,"",_xlfn.MAXIFS(Documents!$E$2:$E$3728,Documents!$A$2:$A$3728,$A9,Documents!$C$2:$C$3728,"obsolete")),"") | W9: =COUNTIFS(Documents!$A$2:$A$3728,$A9) | X9: =COUNTIFS(Documents!$A$2:$A$3728,$A9,Documents!$R$2:$R$3728,"current") | Y9: =HYPERLINK("https://www.neoscapesmaldives.com/wp-content/uploads/MLEAI_Factsheet-March-2025.pdf","2025_MLEAI_Factsheet-March-2025.pdf") | Z9: wedding, events
A10: 9 | B10: Amilla Fushi | C10: ok | D10: =IFERROR(IF(_xlfn.MAXIFS(Documents!$E$2:$E$3728,Documents!$A$2:$A$3728,$A10,Documents!$C$2:$C$3728,"factsheet")=0,"",_xlfn.MAXIFS(Documents!$E$2:$E$3728,Documents!$A$2:$A$3728,$A10,Documents!$C$2:$C$3728,"factsheet")),"") | E10: =IFERROR(IF(_xlfn.MAXIFS(Documents!$E$2:$E$3728,Documents!$A$2:$A$3728,$A10,Documents!$C$2:$C$3728,"wedding")=0,"",_xlfn.MAXIFS(Documents!$E$2:$E$3728,Documents!$A$2:$A$3728,$A10,Documents!$C$2:$C$3728,"wedding")),"") | F10: =IFERROR(IF(_xlfn.MAXIFS(Documents!$E$2:$E$3728,Documents!$A$2:$A$3728,$A10,Documents!$C$2:$C$3728,"events")=0,"",_xlfn.MAXIFS(Documents!$E$2:$E$3728,Documents!$A$2:$A$3728,$A10,Documents!$C$2:$C$3728,"events")),"") | G10: =IFERROR(IF(_xlfn.MAXIFS(Documents!$E$2:$E$3728,Documents!$A$2:$A$3728,$A10,Documents!$C$2:$C$3728,"destination_dining")=0,"",_xlfn.MAXIFS(Documents!$E$2:$E$3728,Documents!$A$2:$A$3728,$A10,Documents!$C$2:$C$3728,"destination_dining")),"") | H10: =IFERROR(IF(_xlfn.MAXIFS(Documents!$E$2:$E$3728,Documents!$A$2:$A$3728,$A10,Documents!$C$2:$C$3728,"map")=0,"",_xlfn.MAXIFS(Documents!$E$2:$E$3728,Documents!$A$2:$A$3728,$A10,Documents!$C$2:$C$3728,"map")),"") | I10: =IFERROR(IF(_xlfn.MAXIFS(Documents!$E$2:$E$3728,Documents!$A$2:$A$3728,$A10,Documents!$C$2:$C$3728,"dive_map")=0,"",_xlfn.MAXIFS(Documents!$E$2:$E$3728,Documents!$A$2:$A$3728,$A10,Documents!$C$2:$C$3728,"dive_map")),"") | J10: =IFERROR(IF(_xlfn.MAXIFS(Documents!$E$2:$E$3728,Documents!$A$2:$A$3728,$A10,Documents!$C$2:$C$3728,"spa_menu")=0,"",_xlfn.MAXIFS(Documents!$E$2:$E$3728,Documents!$A$2:$A$3728,$A10,Documents!$C$2:$C$3728,"spa_menu")),"") | K10: =IFERROR(IF(_xlfn.MAXIFS(Documents!$E$2:$E$3728,Documents!$A$2:$A$3728,$A10,Documents!$C$2:$C$3728,"dining_menu")=0,"",_xlfn.MAXIFS(Documents!$E$2:$E$3728,Documents!$A$2:$A$3728,$A10,Documents!$C$2:$C$3728,"dining_menu")),"") | L10: =IFERROR(IF(_xlfn.MAXIFS(Documents!$E$2:$E$3728,Documents!$A$2:$A$3728,$A10,Documents!$C$2:$C$3728,"dive_prices")=0,"",_xlfn.MAXIFS(Documents!$E$2:$E$3728,Documents!$A$2:$A$3728,$A10,Documents!$C$2:$C$3728,"dive_prices")),"") | M10: =IFERROR(IF(_xlfn.MAXIFS(Documents!$E$2:$E$3728,Documents!$A$2:$A$3728,$A10,Documents!$C$2:$C$3728,"excursions")=0,"",_xlfn.MAXIFS(Documents!$E$2:$E$3728,Documents!$A$2:$A$3728,$A10,Documents!$C$2:$C$3728,"excursions")),"") | N10: =IFERROR(IF(_xlfn.MAXIFS(Documents!$E$2:$E$3728,Documents!$A$2:$A$3728,$A10,Documents!$C$2:$C$3728,"kids")=0,"",_xlfn.MAXIFS(Documents!$E$2:$E$3728,Documents!$A$2:$A$3728,$A10,Documents!$C$2:$C$3728,"kids")),"") | O10: =IFERROR(IF(_xlfn.MAXIFS(Documents!$E$2:$E$3728,Documents!$A$2:$A$3728,$A10,Documents!$C$2:$C$3728,"villa_plans")=0,"",_xlfn.MAXIFS(Documents!$E$2:$E$3728,Documents!$A$2:$A$3728,$A10,Documents!$C$2:$C$3728,"villa_plans")),"") | P10: =IFERROR(IF(_xlfn.MAXIFS(Documents!$E$2:$E$3728,Documents!$A$2:$A$3728,$A10,Documents!$C$2:$C$3728,"all_inclusive")=0,"",_xlfn.MAXIFS(Documents!$E$2:$E$3728,Documents!$A$2:$A$3728,$A10,Documents!$C$2:$C$3728,"all_inclusive")),"") | Q10: =IFERROR(IF(_xlfn.MAXIFS(Documents!$E$2:$E$3728,Documents!$A$2:$A$3728,$A10,Documents!$C$2:$C$3728,"sustainability")=0,"",_xlfn.MAXIFS(Documents!$E$2:$E$3728,Documents!$A$2:$A$3728,$A10,Documents!$C$2:$C$3728,"sustainability")),"") | R10: =IFERROR(IF(_xlfn.MAXIFS(Documents!$E$2:$E$3728,Documents!$A$2:$A$3728,$A10,Documents!$C$2:$C$3728,"calendar")=0,"",_xlfn.MAXIFS(Documents!$E$2:$E$3728,Documents!$A$2:$A$3728,$A10,Documents!$C$2:$C$3728,"calendar")),"") | S10: =IFERROR(IF(_xlfn.MAXIFS(Documents!$E$2:$E$3728,Documents!$A$2:$A$3728,$A10,Documents!$C$2:$C$3728,"brochure")=0,"",_xlfn.MAXIFS(Documents!$E$2:$E$3728,Documents!$A$2:$A$3728,$A10,Documents!$C$2:$C$3728,"brochure")),"") | T10: =IFERROR(IF(_xlfn.MAXIFS(Documents!$E$2:$E$3728,Documents!$A$2:$A$3728,$A10,Documents!$C$2:$C$3728,"press_kit")=0,"",_xlfn.MAXIFS(Documents!$E$2:$E$3728,Documents!$A$2:$A$3728,$A10,Documents!$C$2:$C$3728,"press_kit")),"") | U10: =IFERROR(IF(_xlfn.MAXIFS(Documents!$E$2:$E$3728,Documents!$A$2:$A$3728,$A10,Documents!$C$2:$C$3728,"other")=0,"",_xlfn.MAXIFS(Documents!$E$2:$E$3728,Documents!$A$2:$A$3728,$A10,Documents!$C$2:$C$3728,"other")),"") | V10: =IFERROR(IF(_xlfn.MAXIFS(Documents!$E$2:$E$3728,Documents!$A$2:$A$3728,$A10,Documents!$C$2:$C$3728,"obsolete")=0,"",_xlfn.MAXIFS(Documents!$E$2:$E$3728,Documents!$A$2:$A$3728,$A10,Documents!$C$2:$C$3728,"obsolete")),"") | W10: =COUNTIFS(Documents!$A$2:$A$3728,$A10) | X10: =COUNTIFS(Documents!$A$2:$A$3728,$A10,Documents!$R$2:$R$3728,"current") | Y10: =HYPERLINK("https://amilla.com/wp-content/uploads/Amilla-Maldives_Fact-Sheet_2026.pdf","2026_Amilla-Maldives_Fact-Sheet_2026.pdf") | Z10: events
A11: 10 | B11: Dreamland - The Unique Sea & Lake Resort/Spa | C11: ok | D11: =IFERROR(IF(_xlfn.MAXIFS(Documents!$E$2:$E$3728,Documents!$A$2:$A$3728,$A11,Documents!$C$2:$C$3728,"factsheet")=0,"",_xlfn.MAXIFS(Documents!$E$2:$E$3728,Documents!$A$2:$A$3728,$A11,Documents!$C$2:$C$3728,"factsheet")),"") | E11: =IFERROR(IF(_xlfn.MAXIFS(Documents!$E$2:$E$3728,Documents!$A$2:$A$3728,$A11,Documents!$C$2:$C$3728,"wedding")=0,"",_xlfn.MAXIFS(Documents!$E$2:$E$3728,Documents!$A$2:$A$3728,$A11,Documents!$C$2:$C$3728,"wedding")),"") | F11: =IFERROR(IF(_xlfn.MAXIFS(Documents!$E$2:$E$3728,Documents!$A$2:$A$3728,$A11,Documents!$C$2:$C$3728,"events")=0,"",_xlfn.MAXIFS(Documents!$E$2:$E$3728,Documents!$A$2:$A$3728,$A11,Documents!$C$2:$C$3728,"events")),"") | G11: =IFERROR(IF(_xlfn.MAXIFS(Documents!$E$2:$E$3728,Documents!$A$2:$A$3728,$A11,Documents!$C$2:$C$3728,"destination_dining")=0,"",_xlfn.MAXIFS(Documents!$E$2:$E$3728,Documents!$A$2:$A$3728,$A11,Documents!$C$2:$C$3728,"destination_dining")),"") | H11: =IFERROR(IF(_xlfn.MAXIFS(Documents!$E$2:$E$3728,Documents!$A$2:$A$3728,$A11,Documents!$C$2:$C$3728,"map")=0,"",_xlfn.MAXIFS(Documents!$E$2:$E$3728,Documents!$A$2:$A$3728,$A11,Documents!$C$2:$C$3728,"map")),"") | I11: =IFERROR(IF(_xlfn.MAXIFS(Documents!$E$2:$E$3728,Documents!$A$2:$A$3728,$A11,Documents!$C$2:$C$3728,"dive_map")=0,"",_xlfn.MAXIFS(Documents!$E$2:$E$3728,Documents!$A$2:$A$3728,$A11,Documents!$C$2:$C$3728,"dive_map")),"") | J11: =IFERROR(IF(_xlfn.MAXIFS(Documents!$E$2:$E$3728,Documents!$A$2:$A$3728,$A11,Documents!$C$2:$C$3728,"spa_menu")=0,"",_xlfn.MAXIFS(Documents!$E$2:$E$3728,Documents!$A$2:$A$3728,$A11,Documents!$C$2:$C$3728,"spa_menu")),"") | K11: =IFERROR(IF(_xlfn.MAXIFS(Documents!$E$2:$E$3728,Documents!$A$2:$A$3728,$A11,Documents!$C$2:$C$3728,"dining_menu")=0,"",_xlfn.MAXIFS(Documents!$E$2:$E$3728,Documents!$A$2:$A$3728,$A11,Documents!$C$2:$C$3728,"dining_menu")),"") | L11: =IFERROR(IF(_xlfn.MAXIFS(Documents!$E$2:$E$3728,Documents!$A$2:$A$3728,$A11,Documents!$C$2:$C$3728,"dive_prices")=0,"",_xlfn.MAXIFS(Documents!$E$2:$E$3728,Documents!$A$2:$A$3728,$A11,Documents!$C$2:$C$3728,"dive_prices")),"") | M11: =IFERROR(IF(_xlfn.MAXIFS(Documents!$E$2:$E$3728,Documents!$A$2:$A$3728,$A11,Documents!$C$2:$C$3728,"excursions")=0,"",_xlfn.MAXIFS(Documents!$E$2:$E$3728,Documents!$A$2:$A$3728,$A11,Documents!$C$2:$C$3728,"excursions")),"") | N11: =IFERROR(IF(_xlfn.MAXIFS(Documents!$E$2:$E$3728,Documents!$A$2:$A$3728,$A11,Documents!$C$2:$C$3728,"kids")=0,"",_xlfn.MAXIFS(Documents!$E$2:$E$3728,Documents!$A$2:$A$3728,$A11,Documents!$C$2:$C$3728,"kids")),"") | O11: =IFERROR(IF(_xlfn.MAXIFS(Documents!$E$2:$E$3728,Documents!$A$2:$A$3728,$A11,Documents!$C$2:$C$3728,"villa_plans")=0,"",_xlfn.MAXIFS(Documents!$E$2:$E$3728,Documents!$A$2:$A$3728,$A11,Documents!$C$2:$C$3728,"villa_plans")),"") | P11: =IFERROR(IF(_xlfn.MAXIFS(Documents!$E$2:$E$3728,Documents!$A$2:$A$3728,$A11,Documents!$C$2:$C$3728,"all_inclusive")=0,"",_xlfn.MAXIFS(Documents!$E$2:$E$3728,Documents!$A$2:$A$3728,$A11,Documents!$C$2:$C$3728,"all_inclusive")),"") | Q11: =IFERROR(IF(_xlfn.MAXIFS(Documents!$E$2:$E$3728,Documents!$A$2:$A$3728,$A11,Documents!$C$2:$C$3728,"sustainability")=0,"",_xlfn.MAXIFS(Documents!$E$2:$E$3728,Documents!$A$2:$A$3728,$A11,Documents!$C$2:$C$3728,"sustainability")),"") | R11: =IFERROR(IF(_xlfn.MAXIFS(Documents!$E$2:$E$3728,Documents!$A$2:$A$3728,$A11,Documents!$C$2:$C$3728,"calendar")=0,"",_xlfn.MAXIFS(Documents!$E$2:$E$3728,Documents!$A$2:$A$3728,$A11,Documents!$C$2:$C$3728,"calendar")),"") | S11: =IFERROR(IF(_xlfn.MAXIFS(Documents!$E$2:$E$3728,Documents!$A$2:$A$3728,$A11,Documents!$C$2:$C$3728,"brochure")=0,"",_xlfn.MAXIFS(Documents!$E$2:$E$3728,Documents!$A$2:$A$3728,$A11,Documents!$C$2:$C$3728,"brochure")),"") | T11: =IFERROR(IF(_xlfn.MAXIFS(Documents!$E$2:$E$3728,Documents!$A$2:$A$3728,$A11,Documents!$C$2:$C$3728,"press_kit")=0,"",_xlfn.MAXIFS(Documents!$E$2:$E$3728,Documents!$A$2:$A$3728,$A11,Documents!$C$2:$C$3728,"press_kit")),"") | U11: =IFERROR(IF(_xlfn.MAXIFS(Documents!$E$2:$E$3728,Documents!$A$2:$A$3728,$A11,Documents!$C$2:$C$3728,"other")=0,"",_xlfn.MAXIFS(Documents!$E$2:$E$3728,Documents!$A$2:$A$3728,$A11,Documents!$C$2:$C$3728,"other")),"") | V11: =IFERROR(IF(_xlfn.MAXIFS(Documents!$E$2:$E$3728,Documents!$A$2:$A$3728,$A11,Documents!$C$2:$C$3728,"obsolete")=0,"",_xlfn.MAXIFS(Documents!$E$2:$E$3728,Documents!$A$2:$A$3728,$A11,Documents!$C$2:$C$3728,"obsolete")),"") | W11: =COUNTIFS(Documents!$A$2:$A$3728,$A11) | X11: =COUNTIFS(Documents!$A$2:$A$3728,$A11,Documents!$R$2:$R$3728,"current") | Y11: =HYPERLINK("https://dreamland.com.mv/wp-content/uploads/2024/08/DREAMLAND-GENERAL-INFORMATION-GERMAN-2023.pdf","2023_DREAMLAND-GENERAL-INFORMATION-GERMA") | Z11: events
A12: 11 | B12: Angaga Island Resort and Spa | C12: ok | D12: =IFERROR(IF(_xlfn.MAXIFS(Documents!$E$2:$E$3728,Documents!$A$2:$A$3728,$A12,Documents!$C$2:$C$3728,"factsheet")=0,"",_xlfn.MAXIFS(Documents!$E$2:$E$3728,Documents!$A$2:$A$3728,$A12,Documents!$C$2:$C$3728,"factsheet")),"") | E12: =IFERROR(IF(_xlfn.MAXIFS(Documents!$E$2:$E$3728,Documents!$A$2:$A$3728,$A12,Documents!$C$2:$C$3728,"wedding")=0,"",_xlfn.MAXIFS(Documents!$E$2:$E$3728,Documents!$A$2:$A$3728,$A12,Documents!$C$2:$C$3728,"wedding")),"") | F12: =IFERROR(IF(_xlfn.MAXIFS(Documents!$E$2:$E$3728,Documents!$A$2:$A$3728,$A12,Documents!$C$2:$C$3728,"events")=0,"",_xlfn.MAXIFS(Documents!$E$2:$E$3728,Documents!$A$2:$A$3728,$A12,Documents!$C$2:$C$3728,"events")),"") | G12: =IFERROR(IF(_xlfn.MAXIFS(Documents!$E$2:$E$3728,Documents!$A$2:$A$3728,$A12,Documents!$C$2:$C$3728,"destination_dining")=0,"",_xlfn.MAXIFS(Documents!$E$2:$E$3728,Documents!$A$2:$A$3728,$A12,Documents!$C$2:$C$3728,"destination_dining")),"") | H12: =IFERROR(IF(_xlfn.MAXIFS(Documents!$E$2:$E$3728,Documents!$A$2:$A$3728,$A12,Documents!$C$2:$C$3728,"map")=0,"",_xlfn.MAXIFS(Documents!$E$2:$E$3728,Documents!$A$2:$A$3728,$A12,Documents!$C$2:$C$3728,"map")),"") | I12: =IFERROR(IF(_xlfn.MAXIFS(Documents!$E$2:$E$3728,Documents!$A$2:$A$3728,$A12,Documents!$C$2:$C$3728,"dive_map")=0,"",_xlfn.MAXIFS(Documents!$E$2:$E$3728,Documents!$A$2:$A$3728,$A12,Documents!$C$2:$C$3728,"dive_map")),"") | J12: =IFERROR(IF(_xlfn.MAXIFS(Documents!$E$2:$E$3728,Documents!$A$2:$A$3728,$A12,Documents!$C$2:$C$3728,"spa_menu")=0,"",_xlfn.MAXIFS(Documents!$E$2:$E$3728,Documents!$A$2:$A$3728,$A12,Documents!$C$2:$C$3728,"spa_menu")),"") | K12: =IFERROR(IF(_xlfn.MAXIFS(Documents!$E$2:$E$3728,Documents!$A$2:$A$3728,$A12,Documents!$C$2:$C$3728,"dining_menu")=0,"",_xlfn.MAXIFS(Documents!$E$2:$E$3728,Documents!$A$2:$A$3728,$A12,Documents!$C$2:$C$3728,"dining_menu")),"") | L12: =IFERROR(IF(_xlfn.MAXIFS(Documents!$E$2:$E$3728,Documents!$A$2:$A$3728,$A12,Documents!$C$2:$C$3728,"dive_prices")=0,"",_xlfn.MAXIFS(Documents!$E$2:$E$3728,Documents!$A$2:$A$3728,$A12,Documents!$C$2:$C$3728,"dive_prices")),"") | M12: =IFERROR(IF(_xlfn.MAXIFS(Documents!$E$2:$E$3728,Documents!$A$2:$A$3728,$A12,Documents!$C$2:$C$3728,"excursions")=0,"",_xlfn.MAXIFS(Documents!$E$2:$E$3728,Documents!$A$2:$A$3728,$A12,Documents!$C$2:$C$3728,"excursions")),"") | N12: =IFERROR(IF(_xlfn.MAXIFS(Documents!$E$2:$E$3728,Documents!$A$2:$A$3728,$A12,Documents!$C$2:$C$3728,"kids")=0,"",_xlfn.MAXIFS(Documents!$E$2:$E$3728,Documents!$A$2:$A$3728,$A12,Documents!$C$2:$C$3728,"kids")),"") | O12: =IFERROR(IF(_xlfn.MAXIFS(Documents!$E$2:$E$3728,Documents!$A$2:$A$3728,$A12,Documents!$C$2:$C$3728,"villa_plans")=0,"",_xlfn.MAXIFS(Documents!$E$2:$E$3728,Documents!$A$2:$A$3728,$A12,Documents!$C$2:$C$3728,"villa_plans")),"") | P12: =IFERROR(IF(_xlfn.MAXIFS(Documents!$E$2:$E$3728,Documents!$A$2:$A$3728,$A12,Documents!$C$2:$C$3728,"all_inclusive")=0,"",_xlfn.MAXIFS(Documents!$E$2:$E$3728,Documents!$A$2:$A$3728,$A12,Documents!$C$2:$C$3728,"all_inclusive")),"") | Q12: =IFERROR(IF(_xlfn.MAXIFS(Documents!$E$2:$E$3728,Documents!$A$2:$A$3728,$A12,Documents!$C$2:$C$3728,"sustainability")=0,"",_xlfn.MAXIFS(Documents!$E$2:$E$3728,Documents!$A$2:$A$3728,$A12,Documents!$C$2:$C$3728,"sustainability")),"") | R12: =IFERROR(IF(_xlfn.MAXIFS(Documents!$E$2:$E$3728,Documents!$A$2:$A$3728,$A12,Documents!$C$2:$C$3728,"calendar")=0,"",_xlfn.MAXIFS(Documents!$E$2:$E$3728,Documents!$A$2:$A$3728,$A12,Documents!$C$2:$C$3728,"calendar")),"") | S12: =IFERROR(IF(_xlfn.MAXIFS(Documents!$E$2:$E$3728,Documents!$A$2:$A$3728,$A12,Documents!$C$2:$C$3728,"brochure")=0,"",_xlfn.MAXIFS(Documents!$E$2:$E$3728,Documents!$A$2:$A$3728,$A12,Documents!$C$2:$C$3728,"brochure")),"") | T12: =IFERROR(IF(_xlfn.MAXIFS(Documents!$E$2:$E$3728,Documents!$A$2:$A$3728,$A12,Documents!$C$2:$C$3728,"press_kit")=0,"",_xlfn.MAXIFS(Documents!$E$2:$E$3728,Documents!$A$2:$A$3728,$A12,Documents!$C$2:$C$3728,"press_kit")),"") | U12: =IFERROR(IF(_xlfn.MAXIFS(Documents!$E$2:$E$3728,Documents!$A$2:$A$3728,$A12,Documents!$C$2:$C$3728,"other")=0,"",_xlfn.MAXIFS(Documents!$E$2:$E$3728,Documents!$A$2:$A$3728,$A12,Documents!$C$2:$C$3728,"other")),"") | V12: =IFERROR(IF(_xlfn.MAXIFS(Documents!$E$2:$E$3728,Documents!$A$2:$A$3728,$A12,Documents!$C$2:$C$3728,"obsolete")=0,"",_xlfn.MAXIFS(Documents!$E$2:$E$3728,Documents!$A$2:$A$3728,$A12,Documents!$C$2:$C$3728,"obsolete")),"") | W12: =COUNTIFS(Documents!$A$2:$A$3728,$A12) | X12: =COUNTIFS(Documents!$A$2:$A$3728,$A12,Documents!$R$2:$R$3728,"current") | Y12: =HYPERLINK("https://www.angaga.com.mv/wp-content/uploads/2018/12/GENERAL-INFORMATION.pdf","2018_GENERAL-INFORMATION.pdf") | Z12: events
A13: 12 | B13: Thulhagiri Island Resort & Spa | C13: ok | D13: =IFERROR(IF(_xlfn.MAXIFS(Documents!$E$2:$E$3728,Documents!$A$2:$A$3728,$A13,Documents!$C$2:$C$3728,"factsheet")=0,"",_xlfn.MAXIFS(Documents!$E$2:$E$3728,Documents!$A$2:$A$3728,$A13,Documents!$C$2:$C$3728,"factsheet")),"") | E13: =IFERROR(IF(_xlfn.MAXIFS(Documents!$E$2:$E$3728,Documents!$A$2:$A$3728,$A13,Documents!$C$2:$C$3728,"wedding")=0,"",_xlfn.MAXIFS(Documents!$E$2:$E$3728,Documents!$A$2:$A$3728,$A13,Documents!$C$2:$C$3728,"wedding")),"") | F13: =IFERROR(IF(_xlfn.MAXIFS(Documents!$E$2:$E$3728,Documents!$A$2:$A$3728,$A13,Documents!$C$2:$C$3728,"events")=0,"",_xlfn.MAXIFS(Documents!$E$2:$E$3728,Documents!$A$2:$A$3728,$A13,Documents!$C$2:$C$3728,"events")),"") | G13: =IFERROR(IF(_xlfn.MAXIFS(Documents!$E$2:$E$3728,Documents!$A$2:$A$3728,$A13,Documents!$C$2:$C$3728,"destination_dining")=0,"",_xlfn.MAXIFS(Documents!$E$2:$E$3728,Documents!$A$2:$A$3728,$A13,Documents!$C$2:$C$3728,"destination_dining")),"") | H13: =IFERROR(IF(_xlfn.MAXIFS(Documents!$E$2:$E$3728,Documents!$A$2:$A$3728,$A13,Documents!$C$2:$C$3728,"map")=0,"",_xlfn.MAXIFS(Documents!$E$2:$E$3728,Documents!$A$2:$A$3728,$A13,Documents!$C$2:$C$3728,"map")),"") | I13: =IFERROR(IF(_xlfn.MAXIFS(Documents!$E$2:$E$3728,Documents!$A$2:$A$3728,$A13,Documents!$C$2:$C$3728,"dive_map")=0,"",_xlfn.MAXIFS(Documents!$E$2:$E$3728,Documents!$A$2:$A$3728,$A13,Documents!$C$2:$C$3728,"dive_map")),"") | J13: =IFERROR(IF(_xlfn.MAXIFS(Documents!$E$2:$E$3728,Documents!$A$2:$A$3728,$A13,Documents!$C$2:$C$3728,"spa_menu")=0,"",_xlfn.MAXIFS(Documents!$E$2:$E$3728,Documents!$A$2:$A$3728,$A13,Documents!$C$2:$C$3728,"spa_menu")),"") | K13: =IFERROR(IF(_xlfn.MAXIFS(Documents!$E$2:$E$3728,Documents!$A$2:$A$3728,$A13,Documents!$C$2:$C$3728,"dining_menu")=0,"",_xlfn.MAXIFS(Documents!$E$2:$E$3728,Documents!$A$2:$A$3728,$A13,Documents!$C$2:$C$3728,"dining_menu")),"") | L13: =IFERROR(IF(_xlfn.MAXIFS(Documents!$E$2:$E$3728,Documents!$A$2:$A$3728,$A13,Documents!$C$2:$C$3728,"dive_prices")=0,"",_xlfn.MAXIFS(Documents!$E$2:$E$3728,Documents!$A$2:$A$3728,$A13,Documents!$C$2:$C$3728,"dive_prices")),"") | M13: =IFERROR(IF(_xlfn.MAXIFS(Documents!$E$2:$E$3728,Documents!$A$2:$A$3728,$A13,Documents!$C$2:$C$3728,"excursions")=0,"",_xlfn.MAXIFS(Documents!$E$2:$E$3728,Documents!$A$2:$A$3728,$A13,Documents!$C$2:$C$3728,"excursions")),"") | N13: =IFERROR(IF(_xlfn.MAXIFS(Documents!$E$2:$E$3728,Documents!$A$2:$A$3728,$A13,Documents!$C$2:$C$3728,"kids")=0,"",_xlfn.MAXIFS(Documents!$E$2:$E$3728,Documents!$A$2:$A$3728,$A13,Documents!$C$2:$C$3728,"kids")),"") | O13: =IFERROR(IF(_xlfn.MAXIFS(Documents!$E$2:$E$3728,Documents!$A$2:$A$3728,$A13,Documents!$C$2:$C$3728,"villa_plans")=0,"",_xlfn.MAXIFS(Documents!$E$2:$E$3728,Documents!$A$2:$A$3728,$A13,Documents!$C$2:$C$3728,"villa_plans")),"") | P13: =IFERROR(IF(_xlfn.MAXIFS(Documents!$E$2:$E$3728,Documents!$A$2:$A$3728,$A13,Documents!$C$2:$C$3728,"all_inclusive")=0,"",_xlfn.MAXIFS(Documents!$E$2:$E$3728,Documents!$A$2:$A$3728,$A13,Documents!$C$2:$C$3728,"all_inclusive")),"") | Q13: =IFERROR(IF(_xlfn.MAXIFS(Documents!$E$2:$E$3728,Documents!$A$2:$A$3728,$A13,Documents!$C$2:$C$3728,"sustainability")=0,"",_xlfn.MAXIFS(Documents!$E$2:$E$3728,Documents!$A$2:$A$3728,$A13,Documents!$C$2:$C$3728,"sustainability")),"") | R13: =IFERROR(IF(_xlfn.MAXIFS(Documents!$E$2:$E$3728,Documents!$A$2:$A$3728,$A13,Documents!$C$2:$C$3728,"calendar")=0,"",_xlfn.MAXIFS(Documents!$E$2:$E$3728,Documents!$A$2:$A$3728,$A13,Documents!$C$2:$C$3728,"calendar")),"") | S13: =IFERROR(IF(_xlfn.MAXIFS(Documents!$E$2:$E$3728,Documents!$A$2:$A$3728,$A13,Documents!$C$2:$C$3728,"brochure")=0,"",_xlfn.MAXIFS(Documents!$E$2:$E$3728,Documents!$A$2:$A$3728,$A13,Documents!$C$2:$C$3728,"brochure")),"") | T13: =IFERROR(IF(_xlfn.MAXIFS(Documents!$E$2:$E$3728,Documents!$A$2:$A$3728,$A13,Documents!$C$2:$C$3728,"press_kit")=0,"",_xlfn.MAXIFS(Documents!$E$2:$E$3728,Documents!$A$2:$A$3728,$A13,Documents!$C$2:$C$3728,"press_kit")),"") | U13: =IFERROR(IF(_xlfn.MAXIFS(Documents!$E$2:$E$3728,Documents!$A$2:$A$3728,$A13,Documents!$C$2:$C$3728,"other")=0,"",_xlfn.MAXIFS(Documents!$E$2:$E$3728,Documents!$A$2:$A$3728,$A13,Documents!$C$2:$C$3728,"other")),"") | V13: =IFERROR(IF(_xlfn.MAXIFS(Documents!$E$2:$E$3728,Documents!$A$2:$A$3728,$A13,Documents!$C$2:$C$3728,"obsolete")=0,"",_xlfn.MAXIFS(Documents!$E$2:$E$3728,Documents!$A$2:$A$3728,$A13,Documents!$C$2:$C$3728,"obsolete")),"") | W13: =COUNTIFS(Documents!$A$2:$A$3728,$A13) | X13: =COUNTIFS(Documents!$A$2:$A$3728,$A13,Documents!$R$2:$R$3728,"current") | Z13: factsheet, wedding, events
