Workbook

Sheet Coverage
A1: # | B1: Resort | C1: Official site status | D1: factsheet (latest yr) | E1: wedding (latest yr) | F1: events (latest yr) | G1: map (latest yr) | H1: dive_map (latest yr) | I1: spa_menu (latest yr) | J1: dining_menu (latest yr) | K1: dive_prices (latest yr) | L1: excursions (latest yr) | M1: kids (latest yr) | N1: villa_plans (latest yr) | O1: all_inclusive (latest yr) | P1: sustainability (latest yr) | Q1: calendar (latest yr) | R1: brochure (latest yr) | S1: press_kit (latest yr) | T1: other (latest yr) | U1: obsolete (latest yr) | V1: Total docs | W1: Current docs | X1: Latest factsheet | Y1: Gaps (priority 1) | Z1: Rename notes
A2: 1 | B2: Six Senses Laamu | C2: blocked | D2: =IFERROR(IF(maxifs(Documents!$E$2:$E$1421,Documents!$A$2:$A$1421,$A2,Documents!$C$2:$C$1421,"factsheet")=0,"",maxifs(Documents!$E$2:$E$1421,Documents!$A$2:$A$1421,$A2,Documents!$C$2:$C$1421,"factsheet")),"") | E2: =IFERROR(IF(maxifs(Documents!$E$2:$E$1421,Documents!$A$2:$A$1421,$A2,Documents!$C$2:$C$1421,"wedding")=0,"",maxifs(Documents!$E$2:$E$1421,Documents!$A$2:$A$1421,$A2,Documents!$C$2:$C$1421,"wedding")),"") | F2: =IFERROR(IF(maxifs(Documents!$E$2:$E$1421,Documents!$A$2:$A$1421,$A2,Documents!$C$2:$C$1421,"events")=0,"",maxifs(Documents!$E$2:$E$1421,Documents!$A$2:$A$1421,$A2,Documents!$C$2:$C$1421,"events")),"") | G2: =IFERROR(IF(maxifs(Documents!$E$2:$E$1421,Documents!$A$2:$A$1421,$A2,Documents!$C$2:$C$1421,"map")=0,"",maxifs(Documents!$E$2:$E$1421,Documents!$A$2:$A$1421,$A2,Documents!$C$2:$C$1421,"map")),"") | H2: =IFERROR(IF(maxifs(Documents!$E$2:$E$1421,Documents!$A$2:$A$1421,$A2,Documents!$C$2:$C$1421,"dive_map")=0,"",maxifs(Documents!$E$2:$E$1421,Documents!$A$2:$A$1421,$A2,Documents!$C$2:$C$1421,"dive_map")),"") | I2: =IFERROR(IF(maxifs(Documents!$E$2:$E$1421,Documents!$A$2:$A$1421,$A2,Documents!$C$2:$C$1421,"spa_menu")=0,"",maxifs(Documents!$E$2:$E$1421,Documents!$A$2:$A$1421,$A2,Documents!$C$2:$C$1421,"spa_menu")),"") | J2: =IFERROR(IF(maxifs(Documents!$E$2:$E$1421,Documents!$A$2:$A$1421,$A2,Documents!$C$2:$C$1421,"dining_menu")=0,"",maxifs(Documents!$E$2:$E$1421,Documents!$A$2:$A$1421,$A2,Documents!$C$2:$C$1421,"dining_menu")),"") | K2: =IFERROR(IF(maxifs(Documents!$E$2:$E$1421,Documents!$A$2:$A$1421,$A2,Documents!$C$2:$C$1421,"dive_prices")=0,"",maxifs(Documents!$E$2:$E$1421,Documents!$A$2:$A$1421,$A2,Documents!$C$2:$C$1421,"dive_prices")),"") | L2: =IFERROR(IF(maxifs(Documents!$E$2:$E$1421,Documents!$A$2:$A$1421,$A2,Documents!$C$2:$C$1421,"excursions")=0,"",maxifs(Documents!$E$2:$E$1421,Documents!$A$2:$A$1421,$A2,Documents!$C$2:$C$1421,"excursions")),"") | M2: =IFERROR(IF(maxifs(Documents!$E$2:$E$1421,Documents!$A$2:$A$1421,$A2,Documents!$C$2:$C$1421,"kids")=0,"",maxifs(Documents!$E$2:$E$1421,Documents!$A$2:$A$1421,$A2,Documents!$C$2:$C$1421,"kids")),"") | N2: =IFERROR(IF(maxifs(Documents!$E$2:$E$1421,Documents!$A$2:$A$1421,$A2,Documents!$C$2:$C$1421,"villa_plans")=0,"",maxifs(Documents!$E$2:$E$1421,Documents!$A$2:$A$1421,$A2,Documents!$C$2:$C$1421,"villa_plans")),"") | O2: =IFERROR(IF(maxifs(Documents!$E$2:$E$1421,Documents!$A$2:$A$1421,$A2,Documents!$C$2:$C$1421,"all_inclusive")=0,"",maxifs(Documents!$E$2:$E$1421,Documents!$A$2:$A$1421,$A2,Documents!$C$2:$C$1421,"all_inclusive")),"") | P2: =IFERROR(IF(maxifs(Documents!$E$2:$E$1421,Documents!$A$2:$A$1421,$A2,Documents!$C$2:$C$1421,"sustainability")=0,"",maxifs(Documents!$E$2:$E$1421,Documents!$A$2:$A$1421,$A2,Documents!$C$2:$C$1421,"sustainability")),"") | Q2: =IFERROR(IF(maxifs(Documents!$E$2:$E$1421,Documents!$A$2:$A$1421,$A2,Documents!$C$2:$C$1421,"calendar")=0,"",maxifs(Documents!$E$2:$E$1421,Documents!$A$2:$A$1421,$A2,Documents!$C$2:$C$1421,"calendar")),"") | R2: =IFERROR(IF(maxifs(Documents!$E$2:$E$1421,Documents!$A$2:$A$1421,$A2,Documents!$C$2:$C$1421,"brochure")=0,"",maxifs(Documents!$E$2:$E$1421,Documents!$A$2:$A$1421,$A2,Documents!$C$2:$C$1421,"brochure")),"") | S2: =IFERROR(IF(maxifs(Documents!$E$2:$E$1421,Documents!$A$2:$A$1421,$A2,Documents!$C$2:$C$1421,"press_kit")=0,"",maxifs(Documents!$E$2:$E$1421,Documents!$A$2:$A$1421,$A2,Documents!$C$2:$C$1421,"press_kit")),"") | T2: =IFERROR(IF(maxifs(Documents!$E$2:$E$1421,Documents!$A$2:$A$1421,$A2,Documents!$C$2:$C$1421,"other")=0,"",maxifs(Documents!$E$2:$E$1421,Documents!$A$2:$A$1421,$A2,Documents!$C$2:$C$1421,"other")),"") | U2: =IFERROR(IF(maxifs(Documents!$E$2:$E$1421,Documents!$A$2:$A$1421,$A2,Documents!$C$2:$C$1421,"obsolete")=0,"",maxifs(Documents!$E$2:$E$1421,Documents!$A$2:$A$1421,$A2,Documents!$C$2:$C$1421,"obsolete")),"") | V2: =COUNTIFS(Documents!$A$2:$A$1421,$A2) -> 4 | W2: =COUNTIFS(Documents!$A$2:$A$1421,$A2,Documents!$R$2:$R$1421,"current") -> 2 | X2: =HYPERLINK("https://sales.crownandchamparesorts.com/wp-content/uploads/2026/04/NalaMaldivesFactsheet011125311026Ver030426.pdf","2025_NalaMaldivesFactsheet011125311026Ve") -> 2025_NalaMaldivesFactsheet011125311026Ve | Y2: wedding, events
A3: 2 | B3: Filitheyo Island Resort | C3: unverified | D3: =IFERROR(IF(maxifs(Documents!$E$2:$E$1421,Documents!$A$2:$A$1421,$A3,Documents!$C$2:$C$1421,"factsheet")=0,"",maxifs(Documents!$E$2:$E$1421,Documents!$A$2:$A$1421,$A3,Documents!$C$2:$C$1421,"factsheet")),"") | E3: =IFERROR(IF(maxifs(Documents!$E$2:$E$1421,Documents!$A$2:$A$1421,$A3,Documents!$C$2:$C$1421,"wedding")=0,"",maxifs(Documents!$E$2:$E$1421,Documents!$A$2:$A$1421,$A3,Documents!$C$2:$C$1421,"wedding")),"") | F3: =IFERROR(IF(maxifs(Documents!$E$2:$E$1421,Documents!$A$2:$A$1421,$A3,Documents!$C$2:$C$1421,"events")=0,"",maxifs(Documents!$E$2:$E$1421,Documents!$A$2:$A$1421,$A3,Documents!$C$2:$C$1421,"events")),"") | G3: =IFERROR(IF(maxifs(Documents!$E$2:$E$1421,Documents!$A$2:$A$1421,$A3,Documents!$C$2:$C$1421,"map")=0,"",maxifs(Documents!$E$2:$E$1421,Documents!$A$2:$A$1421,$A3,Documents!$C$2:$C$1421,"map")),"") | H3: =IFERROR(IF(maxifs(Documents!$E$2:$E$1421,Documents!$A$2:$A$1421,$A3,Documents!$C$2:$C$1421,"dive_map")=0,"",maxifs(Documents!$E$2:$E$1421,Documents!$A$2:$A$1421,$A3,Documents!$C$2:$C$1421,"dive_map")),"") | I3: =IFERROR(IF(maxifs(Documents!$E$2:$E$1421,Documents!$A$2:$A$1421,$A3,Documents!$C$2:$C$1421,"spa_menu")=0,"",maxifs(Documents!$E$2:$E$1421,Documents!$A$2:$A$1421,$A3,Documents!$C$2:$C$1421,"spa_menu")),"") | J3: =IFERROR(IF(maxifs(Documents!$E$2:$E$1421,Documents!$A$2:$A$1421,$A3,Documents!$C$2:$C$1421,"dining_menu")=0,"",maxifs(Documents!$E$2:$E$1421,Documents!$A$2:$A$1421,$A3,Documents!$C$2:$C$1421,"dining_menu")),"") | K3: =IFERROR(IF(maxifs(Documents!$E$2:$E$1421,Documents!$A$2:$A$1421,$A3,Documents!$C$2:$C$1421,"dive_prices")=0,"",maxifs(Documents!$E$2:$E$1421,Documents!$A$2:$A$1421,$A3,Documents!$C$2:$C$1421,"dive_prices")),"") | L3: =IFERROR(IF(maxifs(Documents!$E$2:$E$1421,Documents!$A$2:$A$1421,$A3,Documents!$C$2:$C$1421,"excursions")=0,"",maxifs(Documents!$E$2:$E$1421,Documents!$A$2:$A$1421,$A3,Documents!$C$2:$C$1421,"excursions")),"") | M3: =IFERROR(IF(maxifs(Documents!$E$2:$E$1421,Documents!$A$2:$A$1421,$A3,Documents!$C$2:$C$1421,"kids")=0,"",maxifs(Documents!$E$2:$E$1421,Documents!$A$2:$A$1421,$A3,Documents!$C$2:$C$1421,"kids")),"") | N3: =IFERROR(IF(maxifs(Documents!$E$2:$E$1421,Documents!$A$2:$A$1421,$A3,Documents!$C$2:$C$1421,"villa_plans")=0,"",maxifs(Documents!$E$2:$E$1421,Documents!$A$2:$A$1421,$A3,Documents!$C$2:$C$1421,"villa_plans")),"") | O3: =IFERROR(IF(maxifs(Documents!$E$2:$E$1421,Documents!$A$2:$A$1421,$A3,Documents!$C$2:$C$1421,"all_inclusive")=0,"",maxifs(Documents!$E$2:$E$1421,Documents!$A$2:$A$1421,$A3,Documents!$C$2:$C$1421,"all_inclusive")),"") | P3: =IFERROR(IF(maxifs(Documents!$E$2:$E$1421,Documents!$A$2:$A$1421,$A3,Documents!$C$2:$C$1421,"sustainability")=0,"",maxifs(Documents!$E$2:$E$1421,Documents!$A$2:$A$1421,$A3,Documents!$C$2:$C$1421,"sustainability")),"") | Q3: =IFERROR(IF(maxifs(Documents!$E$2:$E$1421,Documents!$A$2:$A$1421,$A3,Documents!$C$2:$C$1421,"calendar")=0,"",maxifs(Documents!$E$2:$E$1421,Documents!$A$2:$A$1421,$A3,Documents!$C$2:$C$1421,"calendar")),"") | R3: =IFERROR(IF(maxifs(Documents!$E$2:$E$1421,Documents!$A$2:$A$1421,$A3,Documents!$C$2:$C$1421,"brochure")=0,"",maxifs(Documents!$E$2:$E$1421,Documents!$A$2:$A$1421,$A3,Documents!$C$2:$C$1421,"brochure")),"") | S3: =IFERROR(IF(maxifs(Documents!$E$2:$E$1421,Documents!$A$2:$A$1421,$A3,Documents!$C$2:$C$1421,"press_kit")=0,"",maxifs(Documents!$E$2:$E$1421,Documents!$A$2:$A$1421,$A3,Documents!$C$2:$C$1421,"press_kit")),"") | T3: =IFERROR(IF(maxifs(Documents!$E$2:$E$1421,Documents!$A$2:$A$1421,$A3,Documents!$C$2:$C$1421,"other")=0,"",maxifs(Documents!$E$2:$E$1421,Documents!$A$2:$A$1421,$A3,Documents!$C$2:$C$1421,"other")),"") | U3: =IFERROR(IF(maxifs(Documents!$E$2:$E$1421,Documents!$A$2:$A$1421,$A3,Documents!$C$2:$C$1421,"obsolete")=0,"",maxifs(Documents!$E$2:$E$1421,Documents!$A$2:$A$1421,$A3,Documents!$C$2:$C$1421,"obsolete")),"") | V3: =COUNTIFS(Documents!$A$2:$A$1421,$A3) -> 0 | W3: =COUNTIFS(Documents!$A$2:$A$1421,$A3,Documents!$R$2:$R$1421,"current") -> 0 | Y3: factsheet, wedding, events
A4: 3 | B4: Adaaran Select Hudhuranfushi | C4: ok | D4: =IFERROR(IF(maxifs(Documents!$E$2:$E$1421,Documents!$A$2:$A$1421,$A4,Documents!$C$2:$C$1421,"factsheet")=0,"",maxifs(Documents!$E$2:$E$1421,Documents!$A$2:$A$1421,$A4,Documents!$C$2:$C$1421,"factsheet")),"") | E4: =IFERROR(IF(maxifs(Documents!$E$2:$E$1421,Documents!$A$2:$A$1421,$A4,Documents!$C$2:$C$1421,"wedding")=0,"",maxifs(Documents!$E$2:$E$1421,Documents!$A$2:$A$1421,$A4,Documents!$C$2:$C$1421,"wedding")),"") | F4: =IFERROR(IF(maxifs(Documents!$E$2:$E$1421,Documents!$A$2:$A$1421,$A4,Documents!$C$2:$C$1421,"events")=0,"",maxifs(Documents!$E$2:$E$1421,Documents!$A$2:$A$1421,$A4,Documents!$C$2:$C$1421,"events")),"") | G4: =IFERROR(IF(maxifs(Documents!$E$2:$E$1421,Documents!$A$2:$A$1421,$A4,Documents!$C$2:$C$1421,"map")=0,"",maxifs(Documents!$E$2:$E$1421,Documents!$A$2:$A$1421,$A4,Documents!$C$2:$C$1421,"map")),"") | H4: =IFERROR(IF(maxifs(Documents!$E$2:$E$1421,Documents!$A$2:$A$1421,$A4,Documents!$C$2:$C$1421,"dive_map")=0,"",maxifs(Documents!$E$2:$E$1421,Documents!$A$2:$A$1421,$A4,Documents!$C$2:$C$1421,"dive_map")),"") | I4: =IFERROR(IF(maxifs(Documents!$E$2:$E$1421,Documents!$A$2:$A$1421,$A4,Documents!$C$2:$C$1421,"spa_menu")=0,"",maxifs(Documents!$E$2:$E$1421,Documents!$A$2:$A$1421,$A4,Documents!$C$2:$C$1421,"spa_menu")),"") | J4: =IFERROR(IF(maxifs(Documents!$E$2:$E$1421,Documents!$A$2:$A$1421,$A4,Documents!$C$2:$C$1421,"dining_menu")=0,"",maxifs(Documents!$E$2:$E$1421,Documents!$A$2:$A$1421,$A4,Documents!$C$2:$C$1421,"dining_menu")),"") | K4: =IFERROR(IF(maxifs(Documents!$E$2:$E$1421,Documents!$A$2:$A$1421,$A4,Documents!$C$2:$C$1421,"dive_prices")=0,"",maxifs(Documents!$E$2:$E$1421,Documents!$A$2:$A$1421,$A4,Documents!$C$2:$C$1421,"dive_prices")),"") | L4: =IFERROR(IF(maxifs(Documents!$E$2:$E$1421,Documents!$A$2:$A$1421,$A4,Documents!$C$2:$C$1421,"excursions")=0,"",maxifs(Documents!$E$2:$E$1421,Documents!$A$2:$A$1421,$A4,Documents!$C$2:$C$1421,"excursions")),"") | M4: =IFERROR(IF(maxifs(Documents!$E$2:$E$1421,Documents!$A$2:$A$1421,$A4,Documents!$C$2:$C$1421,"kids")=0,"",maxifs(Documents!$E$2:$E$1421,Documents!$A$2:$A$1421,$A4,Documents!$C$2:$C$1421,"kids")),"") | N4: =IFERROR(IF(maxifs(Documents!$E$2:$E$1421,Documents!$A$2:$A$1421,$A4,Documents!$C$2:$C$1421,"villa_plans")=0,"",maxifs(Documents!$E$2:$E$1421,Documents!$A$2:$A$1421,$A4,Documents!$C$2:$C$1421,"villa_plans")),"") | O4: =IFERROR(IF(maxifs(Documents!$E$2:$E$1421,Documents!$A$2:$A$1421,$A4,Documents!$C$2:$C$1421,"all_inclusive")=0,"",maxifs(Documents!$E$2:$E$1421,Documents!$A$2:$A$1421,$A4,Documents!$C$2:$C$1421,"all_inclusive")),"") | P4: =IFERROR(IF(maxifs(Documents!$E$2:$E$1421,Documents!$A$2:$A$1421,$A4,Documents!$C$2:$C$1421,"sustainability")=0,"",maxifs(Documents!$E$2:$E$1421,Documents!$A$2:$A$1421,$A4,Documents!$C$2:$C$1421,"sustainability")),"") | Q4: =IFERROR(IF(maxifs(Documents!$E$2:$E$1421,Documents!$A$2:$A$1421,$A4,Documents!$C$2:$C$1421,"calendar")=0,"",maxifs(Documents!$E$2:$E$1421,Documents!$A$2:$A$1421,$A4,Documents!$C$2:$C$1421,"calendar")),"") | R4: =IFERROR(IF(maxifs(Documents!$E$2:$E$1421,Documents!$A$2:$A$1421,$A4,Documents!$C$2:$C$1421,"brochure")=0,"",maxifs(Documents!$E$2:$E$1421,Documents!$A$2:$A$1421,$A4,Documents!$C$2:$C$1421,"brochure")),"") | S4: =IFERROR(IF(maxifs(Documents!$E$2:$E$1421,Documents!$A$2:$A$1421,$A4,Documents!$C$2:$C$1421,"press_kit")=0,"",maxifs(Documents!$E$2:$E$1421,Documents!$A$2:$A$1421,$A4,Documents!$C$2:$C$1421,"press_kit")),"") | T4: =IFERROR(IF(maxifs(Documents!$E$2:$E$1421,Documents!$A$2:$A$1421,$A4,Documents!$C$2:$C$1421,"other")=0,"",maxifs(Documents!$E$2:$E$1421,Documents!$A$2:$A$1421,$A4,Documents!$C$2:$C$1421,"other")),"") | U4: =IFERROR(IF(maxifs(Documents!$E$2:$E$1421,Documents!$A$2:$A$1421,$A4,Documents!$C$2:$C$1421,"obsolete")=0,"",maxifs(Documents!$E$2:$E$1421,Documents!$A$2:$A$1421,$A4,Documents!$C$2:$C$1421,"obsolete")),"") | V4: =COUNTIFS(Documents!$A$2:$A$1421,$A4) -> 21 | W4: =COUNTIFS(Documents!$A$2:$A$1421,$A4,Documents!$R$2:$R$1421,"current") -> 15 | X4: =HYPERLINK("https://www.adaaran.com/selecthudhuranfushi/view-download/?id=menu-16","2026_document.pdf") -> 2026_document.pdf
A5: 4 | B5: Ayada Maldives | C5: ok | D5: =IFERROR(IF(maxifs(Documents!$E$2:$E$1421,Documents!$A$2:$A$1421,$A5,Documents!$C$2:$C$1421,"factsheet")=0,"",maxifs(Documents!$E$2:$E$1421,Documents!$A$2:$A$1421,$A5,Documents!$C$2:$C$1421,"factsheet")),"") | E5: =IFERROR(IF(maxifs(Documents!$E$2:$E$1421,Documents!$A$2:$A$1421,$A5,Documents!$C$2:$C$1421,"wedding")=0,"",maxifs(Documents!$E$2:$E$1421,Documents!$A$2:$A$1421,$A5,Documents!$C$2:$C$1421,"wedding")),"") | F5: =IFERROR(IF(maxifs(Documents!$E$2:$E$1421,Documents!$A$2:$A$1421,$A5,Documents!$C$2:$C$1421,"events")=0,"",maxifs(Documents!$E$2:$E$1421,Documents!$A$2:$A$1421,$A5,Documents!$C$2:$C$1421,"events")),"") | G5: =IFERROR(IF(maxifs(Documents!$E$2:$E$1421,Documents!$A$2:$A$1421,$A5,Documents!$C$2:$C$1421,"map")=0,"",maxifs(Documents!$E$2:$E$1421,Documents!$A$2:$A$1421,$A5,Documents!$C$2:$C$1421,"map")),"") | H5: =IFERROR(IF(maxifs(Documents!$E$2:$E$1421,Documents!$A$2:$A$1421,$A5,Documents!$C$2:$C$1421,"dive_map")=0,"",maxifs(Documents!$E$2:$E$1421,Documents!$A$2:$A$1421,$A5,Documents!$C$2:$C$1421,"dive_map")),"") | I5: =IFERROR(IF(maxifs(Documents!$E$2:$E$1421,Documents!$A$2:$A$1421,$A5,Documents!$C$2:$C$1421,"spa_menu")=0,"",maxifs(Documents!$E$2:$E$1421,Documents!$A$2:$A$1421,$A5,Documents!$C$2:$C$1421,"spa_menu")),"") | J5: =IFERROR(IF(maxifs(Documents!$E$2:$E$1421,Documents!$A$2:$A$1421,$A5,Documents!$C$2:$C$1421,"dining_menu")=0,"",maxifs(Documents!$E$2:$E$1421,Documents!$A$2:$A$1421,$A5,Documents!$C$2:$C$1421,"dining_menu")),"") | K5: =IFERROR(IF(maxifs(Documents!$E$2:$E$1421,Documents!$A$2:$A$1421,$A5,Documents!$C$2:$C$1421,"dive_prices")=0,"",maxifs(Documents!$E$2:$E$1421,Documents!$A$2:$A$1421,$A5,Documents!$C$2:$C$1421,"dive_prices")),"") | L5: =IFERROR(IF(maxifs(Documents!$E$2:$E$1421,Documents!$A$2:$A$1421,$A5,Documents!$C$2:$C$1421,"excursions")=0,"",maxifs(Documents!$E$2:$E$1421,Documents!$A$2:$A$1421,$A5,Documents!$C$2:$C$1421,"excursions")),"") | M5: =IFERROR(IF(maxifs(Documents!$E$2:$E$1421,Documents!$A$2:$A$1421,$A5,Documents!$C$2:$C$1421,"kids")=0,"",maxifs(Documents!$E$2:$E$1421,Documents!$A$2:$A$1421,$A5,Documents!$C$2:$C$1421,"kids")),"") | N5: =IFERROR(IF(maxifs(Documents!$E$2:$E$1421,Documents!$A$2:$A$1421,$A5,Documents!$C$2:$C$1421,"villa_plans")=0,"",maxifs(Documents!$E$2:$E$1421,Documents!$A$2:$A$1421,$A5,Documents!$C$2:$C$1421,"villa_plans")),"") | O5: =IFERROR(IF(maxifs(Documents!$E$2:$E$1421,Documents!$A$2:$A$1421,$A5,Documents!$C$2:$C$1421,"all_inclusive")=0,"",maxifs(Documents!$E$2:$E$1421,Documents!$A$2:$A$1421,$A5,Documents!$C$2:$C$1421,"all_inclusive")),"") | P5: =IFERROR(IF(maxifs(Documents!$E$2:$E$1421,Documents!$A$2:$A$1421,$A5,Documents!$C$2:$C$1421,"sustainability")=0,"",maxifs(Documents!$E$2:$E$1421,Documents!$A$2:$A$1421,$A5,Documents!$C$2:$C$1421,"sustainability")),"") | Q5: =IFERROR(IF(maxifs(Documents!$E$2:$E$1421,Documents!$A$2:$A$1421,$A5,Documents!$C$2:$C$1421,"calendar")=0,"",maxifs(Documents!$E$2:$E$1421,Documents!$A$2:$A$1421,$A5,Documents!$C$2:$C$1421,"calendar")),"") | R5: =IFERROR(IF(maxifs(Documents!$E$2:$E$1421,Documents!$A$2:$A$1421,$A5,Documents!$C$2:$C$1421,"brochure")=0,"",maxifs(Documents!$E$2:$E$1421,Documents!$A$2:$A$1421,$A5,Documents!$C$2:$C$1421,"brochure")),"") | S5: =IFERROR(IF(maxifs(Documents!$E$2:$E$1421,Documents!$A$2:$A$1421,$A5,Documents!$C$2:$C$1421,"press_kit")=0,"",maxifs(Documents!$E$2:$E$1421,Documents!$A$2:$A$1421,$A5,Documents!$C$2:$C$1421,"press_kit")),"") | T5: =IFERROR(IF(maxifs(Documents!$E$2:$E$1421,Documents!$A$2:$A$1421,$A5,Documents!$C$2:$C$1421,"other")=0,"",maxifs(Documents!$E$2:$E$1421,Documents!$A$2:$A$1421,$A5,Documents!$C$2:$C$1421,"other")),"") | U5: =IFERROR(IF(maxifs(Documents!$E$2:$E$1421,Documents!$A$2:$A$1421,$A5,Documents!$C$2:$C$1421,"obsolete")=0,"",maxifs(Documents!$E$2:$E$1421,Documents!$A$2:$A$1421,$A5,Documents!$C$2:$C$1421,"obsolete")),"") | V5: =COUNTIFS(Documents!$A$2:$A$1421,$A5) -> 30 | W5: =COUNTIFS(Documents!$A$2:$A$1421,$A5,Documents!$R$2:$R$1421,"current") -> 2 | X5: =HYPERLINK("https://www.neoscapesmaldives.com/wp-content/uploads/Ayada-Maldives-Factsheet.pdf","2024_Ayada-Maldives-Factsheet.pdf") -> 2024_Ayada-Maldives-Factsheet.pdf | Y5: events
A6: 5 | B6: Bolifushi Island Resort | C6: blocked | D6: =IFERROR(IF(maxifs(Documents!$E$2:$E$1421,Documents!$A$2:$A$1421,$A6,Documents!$C$2:$C$1421,"factsheet")=0,"",maxifs(Documents!$E$2:$E$1421,Documents!$A$2:$A$1421,$A6,Documents!$C$2:$C$1421,"factsheet")),"") | E6: =IFERROR(IF(maxifs(Documents!$E$2:$E$1421,Documents!$A$2:$A$1421,$A6,Documents!$C$2:$C$1421,"wedding")=0,"",maxifs(Documents!$E$2:$E$1421,Documents!$A$2:$A$1421,$A6,Documents!$C$2:$C$1421,"wedding")),"") | F6: =IFERROR(IF(maxifs(Documents!$E$2:$E$1421,Documents!$A$2:$A$1421,$A6,Documents!$C$2:$C$1421,"events")=0,"",maxifs(Documents!$E$2:$E$1421,Documents!$A$2:$A$1421,$A6,Documents!$C$2:$C$1421,"events")),"") | G6: =IFERROR(IF(maxifs(Documents!$E$2:$E$1421,Documents!$A$2:$A$1421,$A6,Documents!$C$2:$C$1421,"map")=0,"",maxifs(Documents!$E$2:$E$1421,Documents!$A$2:$A$1421,$A6,Documents!$C$2:$C$1421,"map")),"") | H6: =IFERROR(IF(maxifs(Documents!$E$2:$E$1421,Documents!$A$2:$A$1421,$A6,Documents!$C$2:$C$1421,"dive_map")=0,"",maxifs(Documents!$E$2:$E$1421,Documents!$A$2:$A$1421,$A6,Documents!$C$2:$C$1421,"dive_map")),"") | I6: =IFERROR(IF(maxifs(Documents!$E$2:$E$1421,Documents!$A$2:$A$1421,$A6,Documents!$C$2:$C$1421,"spa_menu")=0,"",maxifs(Documents!$E$2:$E$1421,Documents!$A$2:$A$1421,$A6,Documents!$C$2:$C$1421,"spa_menu")),"") | J6: =IFERROR(IF(maxifs(Documents!$E$2:$E$1421,Documents!$A$2:$A$1421,$A6,Documents!$C$2:$C$1421,"dining_menu")=0,"",maxifs(Documents!$E$2:$E$1421,Documents!$A$2:$A$1421,$A6,Documents!$C$2:$C$1421,"dining_menu")),"") | K6: =IFERROR(IF(maxifs(Documents!$E$2:$E$1421,Documents!$A$2:$A$1421,$A6,Documents!$C$2:$C$1421,"dive_prices")=0,"",maxifs(Documents!$E$2:$E$1421,Documents!$A$2:$A$1421,$A6,Documents!$C$2:$C$1421,"dive_prices")),"") | L6: =IFERROR(IF(maxifs(Documents!$E$2:$E$1421,Documents!$A$2:$A$1421,$A6,Documents!$C$2:$C$1421,"excursions")=0,"",maxifs(Documents!$E$2:$E$1421,Documents!$A$2:$A$1421,$A6,Documents!$C$2:$C$1421,"excursions")),"") | M6: =IFERROR(IF(maxifs(Documents!$E$2:$E$1421,Documents!$A$2:$A$1421,$A6,Documents!$C$2:$C$1421,"kids")=0,"",maxifs(Documents!$E$2:$E$1421,Documents!$A$2:$A$1421,$A6,Documents!$C$2:$C$1421,"kids")),"") | N6: =IFERROR(IF(maxifs(Documents!$E$2:$E$1421,Documents!$A$2:$A$1421,$A6,Documents!$C$2:$C$1421,"villa_plans")=0,"",maxifs(Documents!$E$2:$E$1421,Documents!$A$2:$A$1421,$A6,Documents!$C$2:$C$1421,"villa_plans")),"") | O6: =IFERROR(IF(maxifs(Documents!$E$2:$E$1421,Documents!$A$2:$A$1421,$A6,Documents!$C$2:$C$1421,"all_inclusive")=0,"",maxifs(Documents!$E$2:$E$1421,Documents!$A$2:$A$1421,$A6,Documents!$C$2:$C$1421,"all_inclusive")),"") | P6: =IFERROR(IF(maxifs(Documents!$E$2:$E$1421,Documents!$A$2:$A$1421,$A6,Documents!$C$2:$C$1421,"sustainability")=0,"",maxifs(Documents!$E$2:$E$1421,Documents!$A$2:$A$1421,$A6,Documents!$C$2:$C$1421,"sustainability")),"") | Q6: =IFERROR(IF(maxifs(Documents!$E$2:$E$1421,Documents!$A$2:$A$1421,$A6,Documents!$C$2:$C$1421,"calendar")=0,"",maxifs(Documents!$E$2:$E$1421,Documents!$A$2:$A$1421,$A6,Documents!$C$2:$C$1421,"calendar")),"") | R6: =IFERROR(IF(maxifs(Documents!$E$2:$E$1421,Documents!$A$2:$A$1421,$A6,Documents!$C$2:$C$1421,"brochure")=0,"",maxifs(Documents!$E$2:$E$1421,Documents!$A$2:$A$1421,$A6,Documents!$C$2:$C$1421,"brochure")),"") | S6: =IFERROR(IF(maxifs(Documents!$E$2:$E$1421,Documents!$A$2:$A$1421,$A6,Documents!$C$2:$C$1421,"press_kit")=0,"",maxifs(Documents!$E$2:$E$1421,Documents!$A$2:$A$1421,$A6,Documents!$C$2:$C$1421,"press_kit")),"") | T6: =IFERROR(IF(maxifs(Documents!$E$2:$E$1421,Documents!$A$2:$A$1421,$A6,Documents!$C$2:$C$1421,"other")=0,"",maxifs(Documents!$E$2:$E$1421,Documents!$A$2:$A$1421,$A6,Documents!$C$2:$C$1421,"other")),"") | U6: =IFERROR(IF(maxifs(Documents!$E$2:$E$1421,Documents!$A$2:$A$1421,$A6,Documents!$C$2:$C$1421,"obsolete")=0,"",maxifs(Documents!$E$2:$E$1421,Documents!$A$2:$A$1421,$A6,Documents!$C$2:$C$1421,"obsolete")),"") | V6: =COUNTIFS(Documents!$A$2:$A$1421,$A6) -> 2 | W6: =COUNTIFS(Documents!$A$2:$A$1421,$A6,Documents!$R$2:$R$1421,"current") -> 0 | X6: =HYPERLINK("https://www.neoscapesmaldives.com/wp-content/uploads/OZEN-RESERVE-BOLIFUSHI-Fact-Sheet.pdf","2023_OZEN-RESERVE-BOLIFUSHI-Fact-Sheet.p") -> 2023_OZEN-RESERVE-BOLIFUSHI-Fact-Sheet.p | Y6: wedding, events | Z6: OZEN Reserve Bolifushi (confirm)
A7: 6 | B7: Joali Being Bodufushi | C7: unreachable | D7: =IFERROR(IF(maxifs(Documents!$E$2:$E$1421,Documents!$A$2:$A$1421,$A7,Documents!$C$2:$C$1421,"factsheet")=0,"",maxifs(Documents!$E$2:$E$1421,Documents!$A$2:$A$1421,$A7,Documents!$C$2:$C$1421,"factsheet")),"") | E7: =IFERROR(IF(maxifs(Documents!$E$2:$E$1421,Documents!$A$2:$A$1421,$A7,Documents!$C$2:$C$1421,"wedding")=0,"",maxifs(Documents!$E$2:$E$1421,Documents!$A$2:$A$1421,$A7,Documents!$C$2:$C$1421,"wedding")),"") | F7: =IFERROR(IF(maxifs(Documents!$E$2:$E$1421,Documents!$A$2:$A$1421,$A7,Documents!$C$2:$C$1421,"events")=0,"",maxifs(Documents!$E$2:$E$1421,Documents!$A$2:$A$1421,$A7,Documents!$C$2:$C$1421,"events")),"") | G7: =IFERROR(IF(maxifs(Documents!$E$2:$E$1421,Documents!$A$2:$A$1421,$A7,Documents!$C$2:$C$1421,"map")=0,"",maxifs(Documents!$E$2:$E$1421,Documents!$A$2:$A$1421,$A7,Documents!$C$2:$C$1421,"map")),"") | H7: =IFERROR(IF(maxifs(Documents!$E$2:$E$1421,Documents!$A$2:$A$1421,$A7,Documents!$C$2:$C$1421,"dive_map")=0,"",maxifs(Documents!$E$2:$E$1421,Documents!$A$2:$A$1421,$A7,Documents!$C$2:$C$1421,"dive_map")),"") | I7: =IFERROR(IF(maxifs(Documents!$E$2:$E$1421,Documents!$A$2:$A$1421,$A7,Documents!$C$2:$C$1421,"spa_menu")=0,"",maxifs(Documents!$E$2:$E$1421,Documents!$A$2:$A$1421,$A7,Documents!$C$2:$C$1421,"spa_menu")),"") | J7: =IFERROR(IF(maxifs(Documents!$E$2:$E$1421,Documents!$A$2:$A$1421,$A7,Documents!$C$2:$C$1421,"dining_menu")=0,"",maxifs(Documents!$E$2:$E$1421,Documents!$A$2:$A$1421,$A7,Documents!$C$2:$C$1421,"dining_menu")),"") | K7: =IFERROR(IF(maxifs(Documents!$E$2:$E$1421,Documents!$A$2:$A$1421,$A7,Documents!$C$2:$C$1421,"dive_prices")=0,"",maxifs(Documents!$E$2:$E$1421,Documents!$A$2:$A$1421,$A7,Documents!$C$2:$C$1421,"dive_prices")),"") | L7: =IFERROR(IF(maxifs(Documents!$E$2:$E$1421,Documents!$A$2:$A$1421,$A7,Documents!$C$2:$C$1421,"excursions")=0,"",maxifs(Documents!$E$2:$E$1421,Documents!$A$2:$A$1421,$A7,Documents!$C$2:$C$1421,"excursions")),"") | M7: =IFERROR(IF(maxifs(Documents!$E$2:$E$1421,Documents!$A$2:$A$1421,$A7,Documents!$C$2:$C$1421,"kids")=0,"",maxifs(Documents!$E$2:$E$1421,Documents!$A$2:$A$1421,$A7,Documents!$C$2:$C$1421,"kids")),"") | N7: =IFERROR(IF(maxifs(Documents!$E$2:$E$1421,Documents!$A$2:$A$1421,$A7,Documents!$C$2:$C$1421,"villa_plans")=0,"",maxifs(Documents!$E$2:$E$1421,Documents!$A$2:$A$1421,$A7,Documents!$C$2:$C$1421,"villa_plans")),"") | O7: =IFERROR(IF(maxifs(Documents!$E$2:$E$1421,Documents!$A$2:$A$1421,$A7,Documents!$C$2:$C$1421,"all_inclusive")=0,"",maxifs(Documents!$E$2:$E$1421,Documents!$A$2:$A$1421,$A7,Documents!$C$2:$C$1421,"all_inclusive")),"") | P7: =IFERROR(IF(maxifs(Documents!$E$2:$E$1421,Documents!$A$2:$A$1421,$A7,Documents!$C$2:$C$1421,"sustainability")=0,"",maxifs(Documents!$E$2:$E$1421,Documents!$A$2:$A$1421,$A7,Documents!$C$2:$C$1421,"sustainability")),"") | Q7: =IFERROR(IF(maxifs(Documents!$E$2:$E$1421,Documents!$A$2:$A$1421,$A7,Documents!$C$2:$C$1421,"calendar")=0,"",maxifs(Documents!$E$2:$E$1421,Documents!$A$2:$A$1421,$A7,Documents!$C$2:$C$1421,"calendar")),"") | R7: =IFERROR(IF(maxifs(Documents!$E$2:$E$1421,Documents!$A$2:$A$1421,$A7,Documents!$C$2:$C$1421,"brochure")=0,"",maxifs(Documents!$E$2:$E$1421,Documents!$A$2:$A$1421,$A7,Documents!$C$2:$C$1421,"brochure")),"") | S7: =IFERROR(IF(maxifs(Documents!$E$2:$E$1421,Documents!$A$2:$A$1421,$A7,Documents!$C$2:$C$1421,"press_kit")=0,"",maxifs(Documents!$E$2:$E$1421,Documents!$A$2:$A$1421,$A7,Documents!$C$2:$C$1421,"press_kit")),"") | T7: =IFERROR(IF(maxifs(Documents!$E$2:$E$1421,Documents!$A$2:$A$1421,$A7,Documents!$C$2:$C$1421,"other")=0,"",maxifs(Documents!$E$2:$E$1421,Documents!$A$2:$A$1421,$A7,Documents!$C$2:$C$1421,"other")),"") | U7: =IFERROR(IF(maxifs(Documents!$E$2:$E$1421,Documents!$A$2:$A$1421,$A7,Documents!$C$2:$C$1421,"obsolete")=0,"",maxifs(Documents!$E$2:$E$1421,Documents!$A$2:$A$1421,$A7,Documents!$C$2:$C$1421,"obsolete")),"") | V7: =COUNTIFS(Documents!$A$2:$A$1421,$A7) -> 2 | W7: =COUNTIFS(Documents!$A$2:$A$1421,$A7,Documents!$R$2:$R$1421,"current") -> 1 | X7: =HYPERLINK("https://www.neoscapesmaldives.com/wp-content/uploads/JoaliBeing_Factsheet_V13.pdf","2025_JoaliBeing_Factsheet_V13.pdf") -> 2025_JoaliBeing_Factsheet_V13.pdf | Y7: wedding, events
A8: 7 | B8: Joali Muravandhoo | C8: unreachable | D8: =IFERROR(IF(maxifs(Documents!$E$2:$E$1421,Documents!$A$2:$A$1421,$A8,Documents!$C$2:$C$1421,"factsheet")=0,"",maxifs(Documents!$E$2:$E$1421,Documents!$A$2:$A$1421,$A8,Documents!$C$2:$C$1421,"factsheet")),"") | E8: =IFERROR(IF(maxifs(Documents!$E$2:$E$1421,Documents!$A$2:$A$1421,$A8,Documents!$C$2:$C$1421,"wedding")=0,"",maxifs(Documents!$E$2:$E$1421,Documents!$A$2:$A$1421,$A8,Documents!$C$2:$C$1421,"wedding")),"") | F8: =IFERROR(IF(maxifs(Documents!$E$2:$E$1421,Documents!$A$2:$A$1421,$A8,Documents!$C$2:$C$1421,"events")=0,"",maxifs(Documents!$E$2:$E$1421,Documents!$A$2:$A$1421,$A8,Documents!$C$2:$C$1421,"events")),"") | G8: =IFERROR(IF(maxifs(Documents!$E$2:$E$1421,Documents!$A$2:$A$1421,$A8,Documents!$C$2:$C$1421,"map")=0,"",maxifs(Documents!$E$2:$E$1421,Documents!$A$2:$A$1421,$A8,Documents!$C$2:$C$1421,"map")),"") | H8: =IFERROR(IF(maxifs(Documents!$E$2:$E$1421,Documents!$A$2:$A$1421,$A8,Documents!$C$2:$C$1421,"dive_map")=0,"",maxifs(Documents!$E$2:$E$1421,Documents!$A$2:$A$1421,$A8,Documents!$C$2:$C$1421,"dive_map")),"") | I8: =IFERROR(IF(maxifs(Documents!$E$2:$E$1421,Documents!$A$2:$A$1421,$A8,Documents!$C$2:$C$1421,"spa_menu")=0,"",maxifs(Documents!$E$2:$E$1421,Documents!$A$2:$A$1421,$A8,Documents!$C$2:$C$1421,"spa_menu")),"") | J8: =IFERROR(IF(maxifs(Documents!$E$2:$E$1421,Documents!$A$2:$A$1421,$A8,Documents!$C$2:$C$1421,"dining_menu")=0,"",maxifs(Documents!$E$2:$E$1421,Documents!$A$2:$A$1421,$A8,Documents!$C$2:$C$1421,"dining_menu")),"") | K8: =IFERROR(IF(maxifs(Documents!$E$2:$E$1421,Documents!$A$2:$A$1421,$A8,Documents!$C$2:$C$1421,"dive_prices")=0,"",maxifs(Documents!$E$2:$E$1421,Documents!$A$2:$A$1421,$A8,Documents!$C$2:$C$1421,"dive_prices")),"") | L8: =IFERROR(IF(maxifs(Documents!$E$2:$E$1421,Documents!$A$2:$A$1421,$A8,Documents!$C$2:$C$1421,"excursions")=0,"",maxifs(Documents!$E$2:$E$1421,Documents!$A$2:$A$1421,$A8,Documents!$C$2:$C$1421,"excursions")),"") | M8: =IFERROR(IF(maxifs(Documents!$E$2:$E$1421,Documents!$A$2:$A$1421,$A8,Documents!$C$2:$C$1421,"kids")=0,"",maxifs(Documents!$E$2:$E$1421,Documents!$A$2:$A$1421,$A8,Documents!$C$2:$C$1421,"kids")),"") | N8: =IFERROR(IF(maxifs(Documents!$E$2:$E$1421,Documents!$A$2:$A$1421,$A8,Documents!$C$2:$C$1421,"villa_plans")=0,"",maxifs(Documents!$E$2:$E$1421,Documents!$A$2:$A$1421,$A8,Documents!$C$2:$C$1421,"villa_plans")),"") | O8: =IFERROR(IF(maxifs(Documents!$E$2:$E$1421,Documents!$A$2:$A$1421,$A8,Documents!$C$2:$C$1421,"all_inclusive")=0,"",maxifs(Documents!$E$2:$E$1421,Documents!$A$2:$A$1421,$A8,Documents!$C$2:$C$1421,"all_inclusive")),"") | P8: =IFERROR(IF(maxifs(Documents!$E$2:$E$1421,Documents!$A$2:$A$1421,$A8,Documents!$C$2:$C$1421,"sustainability")=0,"",maxifs(Documents!$E$2:$E$1421,Documents!$A$2:$A$1421,$A8,Documents!$C$2:$C$1421,"sustainability")),"") | Q8: =IFERROR(IF(maxifs(Documents!$E$2:$E$1421,Documents!$A$2:$A$1421,$A8,Documents!$C$2:$C$1421,"calendar")=0,"",maxifs(Documents!$E$2:$E$1421,Documents!$A$2:$A$1421,$A8,Documents!$C$2:$C$1421,"calendar")),"") | R8: =IFERROR(IF(maxifs(Documents!$E$2:$E$1421,Documents!$A$2:$A$1421,$A8,Documents!$C$2:$C$1421,"brochure")=0,"",maxifs(Documents!$E$2:$E$1421,Documents!$A$2:$A$1421,$A8,Documents!$C$2:$C$1421,"brochure")),"") | S8: =IFERROR(IF(maxifs(Documents!$E$2:$E$1421,Documents!$A$2:$A$1421,$A8,Documents!$C$2:$C$1421,"press_kit")=0,"",maxifs(Documents!$E$2:$E$1421,Documents!$A$2:$A$1421,$A8,Documents!$C$2:$C$1421,"press_kit")),"") | T8: =IFERROR(IF(maxifs(Documents!$E$2:$E$1421,Documents!$A$2:$A$1421,$A8,Documents!$C$2:$C$1421,"other")=0,"",maxifs(Documents!$E$2:$E$1421,Documents!$A$2:$A$1421,$A8,Documents!$C$2:$C$1421,"other")),"") | U8: =IFERROR(IF(maxifs(Documents!$E$2:$E$1421,Documents!$A$2:$A$1421,$A8,Documents!$C$2:$C$1421,"obsolete")=0,"",maxifs(Documents!$E$2:$E$1421,Documents!$A$2:$A$1421,$A8,Documents!$C$2:$C$1421,"obsolete")),"") | V8: =COUNTIFS(Documents!$A$2:$A$1421,$A8) -> 5 | W8: =COUNTIFS(Documents!$A$2:$A$1421,$A8,Documents!$R$2:$R$1421,"current") -> 3 | X8: =HYPERLINK("https://www.neoscapesmaldives.com/wp-content/uploads/JOALI-Maldives-Factsheet.pdf","2023_JOALI-Maldives-Factsheet.pdf") -> 2023_JOALI-Maldives-Factsheet.pdf | Y8: wedding, events
A9: 8 | B9: Hilton Maldives Amingiri Resort & Spa | C9: unverified | D9: =IFERROR(IF(maxifs(Documents!$E$2:$E$1421,Documents!$A$2:$A$1421,$A9,Documents!$C$2:$C$1421,"factsheet")=0,"",maxifs(Documents!$E$2:$E$1421,Documents!$A$2:$A$1421,$A9,Documents!$C$2:$C$1421,"factsheet")),"") | E9: =IFERROR(IF(maxifs(Documents!$E$2:$E$1421,Documents!$A$2:$A$1421,$A9,Documents!$C$2:$C$1421,"wedding")=0,"",maxifs(Documents!$E$2:$E$1421,Documents!$A$2:$A$1421,$A9,Documents!$C$2:$C$1421,"wedding")),"") | F9: =IFERROR(IF(maxifs(Documents!$E$2:$E$1421,Documents!$A$2:$A$1421,$A9,Documents!$C$2:$C$1421,"events")=0,"",maxifs(Documents!$E$2:$E$1421,Documents!$A$2:$A$1421,$A9,Documents!$C$2:$C$1421,"events")),"") | G9: =IFERROR(IF(maxifs(Documents!$E$2:$E$1421,Documents!$A$2:$A$1421,$A9,Documents!$C$2:$C$1421,"map")=0,"",maxifs(Documents!$E$2:$E$1421,Documents!$A$2:$A$1421,$A9,Documents!$C$2:$C$1421,"map")),"") | H9: =IFERROR(IF(maxifs(Documents!$E$2:$E$1421,Documents!$A$2:$A$1421,$A9,Documents!$C$2:$C$1421,"dive_map")=0,"",maxifs(Documents!$E$2:$E$1421,Documents!$A$2:$A$1421,$A9,Documents!$C$2:$C$1421,"dive_map")),"") | I9: =IFERROR(IF(maxifs(Documents!$E$2:$E$1421,Documents!$A$2:$A$1421,$A9,Documents!$C$2:$C$1421,"spa_menu")=0,"",maxifs(Documents!$E$2:$E$1421,Documents!$A$2:$A$1421,$A9,Documents!$C$2:$C$1421,"spa_menu")),"") | J9: =IFERROR(IF(maxifs(Documents!$E$2:$E$1421,Documents!$A$2:$A$1421,$A9,Documents!$C$2:$C$1421,"dining_menu")=0,"",maxifs(Documents!$E$2:$E$1421,Documents!$A$2:$A$1421,$A9,Documents!$C$2:$C$1421,"dining_menu")),"") | K9: =IFERROR(IF(maxifs(Documents!$E$2:$E$1421,Documents!$A$2:$A$1421,$A9,Documents!$C$2:$C$1421,"dive_prices")=0,"",maxifs(Documents!$E$2:$E$1421,Documents!$A$2:$A$1421,$A9,Documents!$C$2:$C$1421,"dive_prices")),"") | L9: =IFERROR(IF(maxifs(Documents!$E$2:$E$1421,Documents!$A$2:$A$1421,$A9,Documents!$C$2:$C$1421,"excursions")=0,"",maxifs(Documents!$E$2:$E$1421,Documents!$A$2:$A$1421,$A9,Documents!$C$2:$C$1421,"excursions")),"") | M9: =IFERROR(IF(maxifs(Documents!$E$2:$E$1421,Documents!$A$2:$A$1421,$A9,Documents!$C$2:$C$1421,"kids")=0,"",maxifs(Documents!$E$2:$E$1421,Documents!$A$2:$A$1421,$A9,Documents!$C$2:$C$1421,"kids")),"") | N9: =IFERROR(IF(maxifs(Documents!$E$2:$E$1421,Documents!$A$2:$A$1421,$A9,Documents!$C$2:$C$1421,"villa_plans")=0,"",maxifs(Documents!$E$2:$E$1421,Documents!$A$2:$A$1421,$A9,Documents!$C$2:$C$1421,"villa_plans")),"") | O9: =IFERROR(IF(maxifs(Documents!$E$2:$E$1421,Documents!$A$2:$A$1421,$A9,Documents!$C$2:$C$1421,"all_inclusive")=0,"",maxifs(Documents!$E$2:$E$1421,Documents!$A$2:$A$1421,$A9,Documents!$C$2:$C$1421,"all_inclusive")),"") | P9: =IFERROR(IF(maxifs(Documents!$E$2:$E$1421,Documents!$A$2:$A$1421,$A9,Documents!$C$2:$C$1421,"sustainability")=0,"",maxifs(Documents!$E$2:$E$1421,Documents!$A$2:$A$1421,$A9,Documents!$C$2:$C$1421,"sustainability")),"") | Q9: =IFERROR(IF(maxifs(Documents!$E$2:$E$1421,Documents!$A$2:$A$1421,$A9,Documents!$C$2:$C$1421,"calendar")=0,"",maxifs(Documents!$E$2:$E$1421,Documents!$A$2:$A$1421,$A9,Documents!$C$2:$C$1421,"calendar")),"") | R9: =IFERROR(IF(maxifs(Documents!$E$2:$E$1421,Documents!$A$2:$A$1421,$A9,Documents!$C$2:$C$1421,"brochure")=0,"",maxifs(Documents!$E$2:$E$1421,Documents!$A$2:$A$1421,$A9,Documents!$C$2:$C$1421,"brochure")),"") | S9: =IFERROR(IF(maxifs(Documents!$E$2:$E$1421,Documents!$A$2:$A$1421,$A9,Documents!$C$2:$C$1421,"press_kit")=0,"",maxifs(Documents!$E$2:$E$1421,Documents!$A$2:$A$1421,$A9,Documents!$C$2:$C$1421,"press_kit")),"") | T9: =IFERROR(IF(maxifs(Documents!$E$2:$E$1421,Documents!$A$2:$A$1421,$A9,Documents!$C$2:$C$1421,"other")=0,"",maxifs(Documents!$E$2:$E$1421,Documents!$A$2:$A$1421,$A9,Documents!$C$2:$C$1421,"other")),"") | U9: =IFERROR(IF(maxifs(Documents!$E$2:$E$1421,Documents!$A$2:$A$1421,$A9,Documents!$C$2:$C$1421,"obsolete")=0,"",maxifs(Documents!$E$2:$E$1421,Documents!$A$2:$A$1421,$A9,Documents!$C$2:$C$1421,"obsolete")),"") | V9: =COUNTIFS(Documents!$A$2:$A$1421,$A9) -> 3 | W9: =COUNTIFS(Documents!$A$2:$A$1421,$A9,Documents!$R$2:$R$1421,"current") -> 2 | X9: =HYPERLINK("https://www.neoscapesmaldives.com/wp-content/uploads/MLEAI_Factsheet-March-2025.pdf","2025_MLEAI_Factsheet-March-2025.pdf") -> 2025_MLEAI_Factsheet-March-2025.pdf | Y9: wedding, events
A10: 9 | B10: Amilla Fushi | C10: ok | D10: =IFERROR(IF(maxifs(Documents!$E$2:$E$1421,Documents!$A$2:$A$1421,$A10,Documents!$C$2:$C$1421,"factsheet")=0,"",maxifs(Documents!$E$2:$E$1421,Documents!$A$2:$A$1421,$A10,Documents!$C$2:$C$1421,"factsheet")),"") | E10: =IFERROR(IF(maxifs(Documents!$E$2:$E$1421,Documents!$A$2:$A$1421,$A10,Documents!$C$2:$C$1421,"wedding")=0,"",maxifs(Documents!$E$2:$E$1421,Documents!$A$2:$A$1421,$A10,Documents!$C$2:$C$1421,"wedding")),"") | F10: =IFERROR(IF(maxifs(Documents!$E$2:$E$1421,Documents!$A$2:$A$1421,$A10,Documents!$C$2:$C$1421,"events")=0,"",maxifs(Documents!$E$2:$E$1421,Documents!$A$2:$A$1421,$A10,Documents!$C$2:$C$1421,"events")),"") | G10: =IFERROR(IF(maxifs(Documents!$E$2:$E$1421,Documents!$A$2:$A$1421,$A10,Documents!$C$2:$C$1421,"map")=0,"",maxifs(Documents!$E$2:$E$1421,Documents!$A$2:$A$1421,$A10,Documents!$C$2:$C$1421,"map")),"") | H10: =IFERROR(IF(maxifs(Documents!$E$2:$E$1421,Documents!$A$2:$A$1421,$A10,Documents!$C$2:$C$1421,"dive_map")=0,"",maxifs(Documents!$E$2:$E$1421,Documents!$A$2:$A$1421,$A10,Documents!$C$2:$C$1421,"dive_map")),"") | I10: =IFERROR(IF(maxifs(Documents!$E$2:$E$1421,Documents!$A$2:$A$1421,$A10,Documents!$C$2:$C$1421,"spa_menu")=0,"",maxifs(Documents!$E$2:$E$1421,Documents!$A$2:$A$1421,$A10,Documents!$C$2:$C$1421,"spa_menu")),"") | J10: =IFERROR(IF(maxifs(Documents!$E$2:$E$1421,Documents!$A$2:$A$1421,$A10,Documents!$C$2:$C$1421,"dining_menu")=0,"",maxifs(Documents!$E$2:$E$1421,Documents!$A$2:$A$1421,$A10,Documents!$C$2:$C$1421,"dining_menu")),"") | K10: =IFERROR(IF(maxifs(Documents!$E$2:$E$1421,Documents!$A$2:$A$1421,$A10,Documents!$C$2:$C$1421,"dive_prices")=0,"",maxifs(Documents!$E$2:$E$1421,Documents!$A$2:$A$1421,$A10,Documents!$C$2:$C$1421,"dive_prices")),"") | L10: =IFERROR(IF(maxifs(Documents!$E$2:$E$1421,Documents!$A$2:$A$1421,$A10,Documents!$C$2:$C$1421,"excursions")=0,"",maxifs(Documents!$E$2:$E$1421,Documents!$A$2:$A$1421,$A10,Documents!$C$2:$C$1421,"excursions")),"") | M10: =IFERROR(IF(maxifs(Documents!$E$2:$E$1421,Documents!$A$2:$A$1421,$A10,Documents!$C$2:$C$1421,"kids")=0,"",maxifs(Documents!$E$2:$E$1421,Documents!$A$2:$A$1421,$A10,Documents!$C$2:$C$1421,"kids")),"") | N10: =IFERROR(IF(maxifs(Documents!$E$2:$E$1421,Documents!$A$2:$A$1421,$A10,Documents!$C$2:$C$1421,"villa_plans")=0,"",maxifs(Documents!$E$2:$E$1421,Documents!$A$2:$A$1421,$A10,Documents!$C$2:$C$1421,"villa_plans")),"") | O10: =IFERROR(IF(maxifs(Documents!$E$2:$E$1421,Documents!$A$2:$A$1421,$A10,Documents!$C$2:$C$1421,"all_inclusive")=0,"",maxifs(Documents!$E$2:$E$1421,Documents!$A$2:$A$1421,$A10,Documents!$C$2:$C$1421,"all_inclusive")),"") | P10: =IFERROR(IF(maxifs(Documents!$E$2:$E$1421,Documents!$A$2:$A$1421,$A10,Documents!$C$2:$C$1421,"sustainability")=0,"",maxifs(Documents!$E$2:$E$1421,Documents!$A$2:$A$1421,$A10,Documents!$C$2:$C$1421,"sustainability")),"") | Q10: =IFERROR(IF(maxifs(Documents!$E$2:$E$1421,Documents!$A$2:$A$1421,$A10,Documents!$C$2:$C$1421,"calendar")=0,"",maxifs(Documents!$E$2:$E$1421,Documents!$A$2:$A$1421,$A10,Documents!$C$2:$C$1421,"calendar")),"") | R10: =IFERROR(IF(maxifs(Documents!$E$2:$E$1421,Documents!$A$2:$A$1421,$A10,Documents!$C$2:$C$1421,"brochure")=0,"",maxifs(Documents!$E$2:$E$1421,Documents!$A$2:$A$1421,$A10,Documents!$C$2:$C$1421,"brochure")),"") | S10: =IFERROR(IF(maxifs(Documents!$E$2:$E$1421,Documents!$A$2:$A$1421,$A10,Documents!$C$2:$C$1421,"press_kit")=0,"",maxifs(Documents!$E$2:$E$1421,Documents!$A$2:$A$1421,$A10,Documents!$C$2:$C$1421,"press_kit")),"") | T10: =IFERROR(IF(maxifs(Documents!$E$2:$E$1421,Documents!$A$2:$A$1421,$A10,Documents!$C$2:$C$1421,"other")=0,"",maxifs(Documents!$E$2:$E$1421,Documents!$A$2:$A$1421,$A10,Documents!$C$2:$C$1421,"other")),"") | U10: =IFERROR(IF(maxifs(Documents!$E$2:$E$1421,Documents!$A$2:$A$1421,$A10,Documents!$C$2:$C$1421,"obsolete")=0,"",maxifs(Documents!$E$2:$E$1421,Documents!$A$2:$A$1421,$A10,Documents!$C$2:$C$1421,"obsolete")),"") | V10: =COUNTIFS(Documents!$A$2:$A$1421,$A10) -> 93 | W10: =COUNTIFS(Documents!$A$2:$A$1421,$A10,Documents!$R$2:$R$1421,"current") -> 43 | X10: =HYPERLINK("https://amilla.com/wp-content/uploads/Amilla-Maldives_Fact-Sheet_2026.pdf","2026_Amilla-Maldives_Fact-Sheet_2026.pdf") -> 2026_Amilla-Maldives_Fact-Sheet_2026.pdf | Y10: events
A11: 10 | B11: Dreamland - The Unique Sea & Lake Resort/Spa | C11: ok | D11: =IFERROR(IF(maxifs(Documents!$E$2:$E$1421,Documents!$A$2:$A$1421,$A11,Documents!$C$2:$C$1421,"factsheet")=0,"",maxifs(Documents!$E$2:$E$1421,Documents!$A$2:$A$1421,$A11,Documents!$C$2:$C$1421,"factsheet")),"") | E11: =IFERROR(IF(maxifs(Documents!$E$2:$E$1421,Documents!$A$2:$A$1421,$A11,Documents!$C$2:$C$1421,"wedding")=0,"",maxifs(Documents!$E$2:$E$1421,Documents!$A$2:$A$1421,$A11,Documents!$C$2:$C$1421,"wedding")),"") | F11: =IFERROR(IF(maxifs(Documents!$E$2:$E$1421,Documents!$A$2:$A$1421,$A11,Documents!$C$2:$C$1421,"events")=0,"",maxifs(Documents!$E$2:$E$1421,Documents!$A$2:$A$1421,$A11,Documents!$C$2:$C$1421,"events")),"") | G11: =IFERROR(IF(maxifs(Documents!$E$2:$E$1421,Documents!$A$2:$A$1421,$A11,Documents!$C$2:$C$1421,"map")=0,"",maxifs(Documents!$E$2:$E$1421,Documents!$A$2:$A$1421,$A11,Documents!$C$2:$C$1421,"map")),"") | H11: =IFERROR(IF(maxifs(Documents!$E$2:$E$1421,Documents!$A$2:$A$1421,$A11,Documents!$C$2:$C$1421,"dive_map")=0,"",maxifs(Documents!$E$2:$E$1421,Documents!$A$2:$A$1421,$A11,Documents!$C$2:$C$1421,"dive_map")),"") | I11: =IFERROR(IF(maxifs(Documents!$E$2:$E$1421,Documents!$A$2:$A$1421,$A11,Documents!$C$2:$C$1421,"spa_menu")=0,"",maxifs(Documents!$E$2:$E$1421,Documents!$A$2:$A$1421,$A11,Documents!$C$2:$C$1421,"spa_menu")),"") | J11: =IFERROR(IF(maxifs(Documents!$E$2:$E$1421,Documents!$A$2:$A$1421,$A11,Documents!$C$2:$C$1421,"dining_menu")=0,"",maxifs(Documents!$E$2:$E$1421,Documents!$A$2:$A$1421,$A11,Documents!$C$2:$C$1421,"dining_menu")),"") | K11: =IFERROR(IF(maxifs(Documents!$E$2:$E$1421,Documents!$A$2:$A$1421,$A11,Documents!$C$2:$C$1421,"dive_prices")=0,"",maxifs(Documents!$E$2:$E$1421,Documents!$A$2:$A$1421,$A11,Documents!$C$2:$C$1421,"dive_prices")),"") | L11: =IFERROR(IF(maxifs(Documents!$E$2:$E$1421,Documents!$A$2:$A$1421,$A11,Documents!$C$2:$C$1421,"excursions")=0,"",maxifs(Documents!$E$2:$E$1421,Documents!$A$2:$A$1421,$A11,Documents!$C$2:$C$1421,"excursions")),"") | M11: =IFERROR(IF(maxifs(Documents!$E$2:$E$1421,Documents!$A$2:$A$1421,$A11,Documents!$C$2:$C$1421,"kids")=0,"",maxifs(Documents!$E$2:$E$1421,Documents!$A$2:$A$1421,$A11,Documents!$C$2:$C$1421,"kids")),"") | N11: =IFERROR(IF(maxifs(Documents!$E$2:$E$1421,Documents!$A$2:$A$1421,$A11,Documents!$C$2:$C$1421,"villa_plans")=0,"",maxifs(Documents!$E$2:$E$1421,Documents!$A$2:$A$1421,$A11,Documents!$C$2:$C$1421,"villa_plans")),"") | O11: =IFERROR(IF(maxifs(Documents!$E$2:$E$1421,Documents!$A$2:$A$1421,$A11,Documents!$C$2:$C$1421,"all_inclusive")=0,"",maxifs(Documents!$E$2:$E$1421,Documents!$A$2:$A$1421,$A11,Documents!$C$2:$C$1421,"all_inclusive")),"") | P11: =IFERROR(IF(maxifs(Documents!$E$2:$E$1421,Documents!$A$2:$A$1421,$A11,Documents!$C$2:$C$1421,"sustainability")=0,"",maxifs(Documents!$E$2:$E$1421,Documents!$A$2:$A$1421,$A11,Documents!$C$2:$C$1421,"sustainability")),"") | Q11: =IFERROR(IF(maxifs(Documents!$E$2:$E$1421,Documents!$A$2:$A$1421,$A11,Documents!$C$2:$C$1421,"calendar")=0,"",maxifs(Documents!$E$2:$E$1421,Documents!$A$2:$A$1421,$A11,Documents!$C$2:$C$1421,"calendar")),"") | R11: =IFERROR(IF(maxifs(Documents!$E$2:$E$1421,Documents!$A$2:$A$1421,$A11,Documents!$C$2:$C$1421,"brochure")=0,"",maxifs(Documents!$E$2:$E$1421,Documents!$A$2:$A$1421,$A11,Documents!$C$2:$C$1421,"brochure")),"") | S11: =IFERROR(IF(maxifs(Documents!$E$2:$E$1421,Documents!$A$2:$A$1421,$A11,Documents!$C$2:$C$1421,"press_kit")=0,"",maxifs(Documents!$E$2:$E$1421,Documents!$A$2:$A$1421,$A11,Documents!$C$2:$C$1421,"press_kit")),"") | T11: =IFERROR(IF(maxifs(Documents!$E$2:$E$1421,Documents!$A$2:$A$1421,$A11,Documents!$C$2:$C$1421,"other")=0,"",maxifs(Documents!$E$2:$E$1421,Documents!$A$2:$A$1421,$A11,Documents!$C$2:$C$1421,"other")),"") | U11: =IFERROR(IF(maxifs(Documents!$E$2:$E$1421,Documents!$A$2:$A$1421,$A11,Documents!$C$2:$C$1421,"obsolete")=0,"",maxifs(Documents!$E$2:$E$1421,Documents!$A$2:$A$1421,$A11,Documents!$C$2:$C$1421,"obsolete")),"") | V11: =COUNTIFS(Documents!$A$2:$A$1421,$A11) -> 22 | W11: =COUNTIFS(Documents!$A$2:$A$1421,$A11,Documents!$R$2:$R$1421,"current") -> 0 | X11: =HYPERLINK("https://dreamland.com.mv/wp-content/uploads/2024/08/DREAMLAND-GENERAL-INFORMATION-GERMAN-2023.pdf","2023_DREAMLAND-GENERAL-INFORMATION-GERMA") -> 2023_DREAMLAND-GENERAL-INFORMATION-GERMA | Y11: events
A12: 11 | B12: Angaga Island Resort and Spa | C12: ok | D12: =IFERROR(IF(maxifs(Documents!$E$2:$E$1421,Documents!$A$2:$A$1421,$A12,Documents!$C$2:$C$1421,"factsheet")=0,"",maxifs(Documents!$E$2:$E$1421,Documents!$A$2:$A$1421,$A12,Documents!$C$2:$C$1421,"factsheet")),"") | E12: =IFERROR(IF(maxifs(Documents!$E$2:$E$1421,Documents!$A$2:$A$1421,$A12,Documents!$C$2:$C$1421,"wedding")=0,"",maxifs(Documents!$E$2:$E$1421,Documents!$A$2:$A$1421,$A12,Documents!$C$2:$C$1421,"wedding")),"") | F12: =IFERROR(IF(maxifs(Documents!$E$2:$E$1421,Documents!$A$2:$A$1421,$A12,Documents!$C$2:$C$1421,"events")=0,"",maxifs(Documents!$E$2:$E$1421,Documents!$A$2:$A$1421,$A12,Documents!$C$2:$C$1421,"events")),"") | G12: =IFERROR(IF(maxifs(Documents!$E$2:$E$1421,Documents!$A$2:$A$1421,$A12,Documents!$C$2:$C$1421,"map")=0,"",maxifs(Documents!$E$2:$E$1421,Documents!$A$2:$A$1421,$A12,Documents!$C$2:$C$1421,"map")),"") | H12: =IFERROR(IF(maxifs(Documents!$E$2:$E$1421,Documents!$A$2:$A$1421,$A12,Documents!$C$2:$C$1421,"dive_map")=0,"",maxifs(Documents!$E$2:$E$1421,Documents!$A$2:$A$1421,$A12,Documents!$C$2:$C$1421,"dive_map")),"") | I12: =IFERROR(IF(maxifs(Documents!$E$2:$E$1421,Documents!$A$2:$A$1421,$A12,Documents!$C$2:$C$1421,"spa_menu")=0,"",maxifs(Documents!$E$2:$E$1421,Documents!$A$2:$A$1421,$A12,Documents!$C$2:$C$1421,"spa_menu")),"") | J12: =IFERROR(IF(maxifs(Documents!$E$2:$E$1421,Documents!$A$2:$A$1421,$A12,Documents!$C$2:$C$1421,"dining_menu")=0,"",maxifs(Documents!$E$2:$E$1421,Documents!$A$2:$A$1421,$A12,Documents!$C$2:$C$1421,"dining_menu")),"") | K12: =IFERROR(IF(maxifs(Documents!$E$2:$E$1421,Documents!$A$2:$A$1421,$A12,Documents!$C$2:$C$1421,"dive_prices")=0,"",maxifs(Documents!$E$2:$E$1421,Documents!$A$2:$A$1421,$A12,Documents!$C$2:$C$1421,"dive_prices")),"") | L12: =IFERROR(IF(maxifs(Documents!$E$2:$E$1421,Documents!$A$2:$A$1421,$A12,Documents!$C$2:$C$1421,"excursions")=0,"",maxifs(Documents!$E$2:$E$1421,Documents!$A$2:$A$1421,$A12,Documents!$C$2:$C$1421,"excursions")),"") | M12: =IFERROR(IF(maxifs(Documents!$E$2:$E$1421,Documents!$A$2:$A$1421,$A12,Documents!$C$2:$C$1421,"kids")=0,"",maxifs(Documents!$E$2:$E$1421,Documents!$A$2:$A$1421,$A12,Documents!$C$2:$C$1421,"kids")),"") | N12: =IFERROR(IF(maxifs(Documents!$E$2:$E$1421,Documents!$A$2:$A$1421,$A12,Documents!$C$2:$C$1421,"villa_plans")=0,"",maxifs(Documents!$E$2:$E$1421,Documents!$A$2:$A$1421,$A12,Documents!$C$2:$C$1421,"villa_plans")),"") | O12: =IFERROR(IF(maxifs(Documents!$E$2:$E$1421,Documents!$A$2:$A$1421,$A12,Documents!$C$2:$C$1421,"all_inclusive")=0,"",maxifs(Documents!$E$2:$E$1421,Documents!$A$2:$A$1421,$A12,Documents!$C$2:$C$1421,"all_inclusive")),"") | P12: =IFERROR(IF(maxifs(Documents!$E$2:$E$1421,Documents!$A$2:$A$1421,$A12,Documents!$C$2:$C$1421,"sustainability")=0,"",maxifs(Documents!$E$2:$E$1421,Documents!$A$2:$A$1421,$A12,Documents!$C$2:$C$1421,"sustainability")),"") | Q12: =IFERROR(IF(maxifs(Documents!$E$2:$E$1421,Documents!$A$2:$A$1421,$A12,Documents!$C$2:$C$1421,"calendar")=0,"",maxifs(Documents!$E$2:$E$1421,Documents!$A$2:$A$1421,$A12,Documents!$C$2:$C$1421,"calendar")),"") | R12: =IFERROR(IF(maxifs(Documents!$E$2:$E$1421,Documents!$A$2:$A$1421,$A12,Documents!$C$2:$C$1421,"brochure")=0,"",maxifs(Documents!$E$2:$E$1421,Documents!$A$2:$A$1421,$A12,Documents!$C$2:$C$1421,"brochure")),"") | S12: =IFERROR(IF(maxifs(Documents!$E$2:$E$1421,Documents!$A$2:$A$1421,$A12,Documents!$C$2:$C$1421,"press_kit")=0,"",maxifs(Documents!$E$2:$E$1421,Documents!$A$2:$A$1421,$A12,Documents!$C$2:$C$1421,"press_kit")),"") | T12: =IFERROR(IF(maxifs(Documents!$E$2:$E$1421,Documents!$A$2:$A$1421,$A12,Documents!$C$2:$C$1421,"other")=0,"",maxifs(Documents!$E$2:$E$1421,Documents!$A$2:$A$1421,$A12,Documents!$C$2:$C$1421,"other")),"") | U12: =IFERROR(IF(maxifs(Documents!$E$2:$E$1421,Documents!$A$2:$A$1421,$A12,Documents!$C$2:$C$1421,"obsolete")=0,"",maxifs(Documents!$E$2:$E$1421,Documents!$A$2:$A$1421,$A12,Documents!$C$2:$C$1421,"obsolete")),"") | V12: =COUNTIFS(Documents!$A$2:$A$1421,$A12) -> 27 | W12: =COUNTIFS(Documents!$A$2:$A$1421,$A12,Documents!$R$2:$R$1421,"current") -> 5 | X12: =HYPERLINK("https://www.angaga.com.mv/wp-content/uploads/2018/12/GENERAL-INFORMATION.pdf","2018_GENERAL-INFORMATION.pdf") -> 2018_GENERAL-INFORMATION.pdf | Y12: events
A13: 12 | B13: Thulhagiri Island Resort & Spa | C13: ok | D13: =IFERROR(IF(maxifs(Documents!$E$2:$E$1421,Documents!$A$2:$A$1421,$A13,Documents!$C$2:$C$1421,"factsheet")=0,"",maxifs(Documents!$E$2:$E$1421,Documents!$A$2:$A$1421,$A13,Documents!$C$2:$C$1421,"factsheet")),"") | E13: =IFERROR(IF(maxifs(Documents!$E$2:$E$1421,Documents!$A$2:$A$1421,$A13,Documents!$C$2:$C$1421,"wedding")=0,"",maxifs(Documents!$E$2:$E$1421,Documents!$A$2:$A$1421,$A13,Documents!$C$2:$C$1421,"wedding")),"") | F13: =IFERROR(IF(maxifs(Documents!$E$2:$E$1421,Documents!$A$2:$A$1421,$A13,Documents!$C$2:$C$1421,"events")=0,"",maxifs(Documents!$E$2:$E$1421,Documents!$A$2:$A$1421,$A13,Documents!$C$2:$C$1421,"events")),"") | G13: =IFERROR(IF(maxifs(Documents!$E$2:$E$1421,Documents!$A$2:$A$1421,$A13,Documents!$C$2:$C$1421,"map")=0,"",maxifs(Documents!$E$2:$E$1421,Documents!$A$2:$A$1421,$A13,Documents!$C$2:$C$1421,"map")),"") | H13: =IFERROR(IF(maxifs(Documents!$E$2:$E$1421,Documents!$A$2:$A$1421,$A13,Documents!$C$2:$C$1421,"dive_map")=0,"",maxifs(Documents!$E$2:$E$1421,Documents!$A$2:$A$1421,$A13,Documents!$C$2:$C$1421,"dive_map")),"") | I13: =IFERROR(IF(maxifs(Documents!$E$2:$E$1421,Documents!$A$2:$A$1421,$A13,Documents!$C$2:$C$1421,"spa_menu")=0,"",maxifs(Documents!$E$2:$E$1421,Documents!$A$2:$A$1421,$A13,Documents!$C$2:$C$1421,"spa_menu")),"") | J13: =IFERROR(IF(maxifs(Documents!$E$2:$E$1421,Documents!$A$2:$A$1421,$A13,Documents!$C$2:$C$1421,"dining_menu")=0,"",maxifs(Documents!$E$2:$E$1421,Documents!$A$2:$A$1421,$A13,Documents!$C$2:$C$1421,"dining_menu")),"") | K13: =IFERROR(IF(maxifs(Documents!$E$2:$E$1421,Documents!$A$2:$A$1421,$A13,Documents!$C$2:$C$1421,"dive_prices")=0,"",maxifs(Documents!$E$2:$E$1421,Documents!$A$2:$A$1421,$A13,Documents!$C$2:$C$1421,"dive_prices")),"") | L13: =IFERROR(IF(maxifs(Documents!$E$2:$E$1421,Documents!$A$2:$A$1421,$A13,Documents!$C$2:$C$1421,"excursions")=0,"",maxifs(Documents!$E$2:$E$1421,Documents!$A$2:$A$1421,$A13,Documents!$C$2:$C$1421,"excursions")),"") | M13: =IFERROR(IF(maxifs(Documents!$E$2:$E$1421,Documents!$A$2:$A$1421,$A13,Documents!$C$2:$C$1421,"kids")=0,"",maxifs(Documents!$E$2:$E$1421,Documents!$A$2:$A$1421,$A13,Documents!$C$2:$C$1421,"kids")),"") | N13: =IFERROR(IF(maxifs(Documents!$E$2:$E$1421,Documents!$A$2:$A$1421,$A13,Documents!$C$2:$C$1421,"villa_plans")=0,"",maxifs(Documents!$E$2:$E$1421,Documents!$A$2:$A$1421,$A13,Documents!$C$2:$C$1421,"villa_plans")),"") | O13: =IFERROR(IF(maxifs(Documents!$E$2:$E$1421,Documents!$A$2:$A$1421,$A13,Documents!$C$2:$C$1421,"all_inclusive")=0,"",maxifs(Documents!$E$2:$E$1421,Documents!$A$2:$A$1421,$A13,Documents!$C$2:$C$1421,"all_inclusive")),"") | P13: =IFERROR(IF(maxifs(Documents!$E$2:$E$1421,Documents!$A$2:$A$1421,$A13,Documents!$C$2:$C$1421,"sustainability")=0,"",maxifs(Documents!$E$2:$E$1421,Documents!$A$2:$A$1421,$A13,Documents!$C$2:$C$1421,"sustainability")),"") | Q13: =IFERROR(IF(maxifs(Documents!$E$2:$E$1421,Documents!$A$2:$A$1421,$A13,Documents!$C$2:$C$1421,"calendar")=0,"",maxifs(Documents!$E$2:$E$1421,Documents!$A$2:$A$1421,$A13,Documents!$C$2:$C$1421,"calendar")),"") | R13: =IFERROR(IF(maxifs(Documents!$E$2:$E$1421,Documents!$A$2:$A$1421,$A13,Documents!$C$2:$C$1421,"brochure")=0,"",maxifs(Documents!$E$2:$E$1421,Documents!$A$2:$A$1421,$A13,Documents!$C$2:$C$1421,"brochure")),"") | S13: =IFERROR(IF(maxifs(Documents!$E$2:$E$1421,Documents!$A$2:$A$1421,$A13,Documents!$C$2:$C$1421,"press_kit")=0,"",maxifs(Documents!$E$2:$E$1421,Documents!$A$2:$A$1421,$A13,Documents!$C$2:$C$1421,"press_kit")),"") | T13: =IFERROR(IF(maxifs(Documents!$E$2:$E$1421,Documents!$A$2:$A$1421,$A13,Documents!$C$2:$C$1421,"other")=0,"",maxifs(Documents!$E$2:$E$1421,Documents!$A$2:$A$1421,$A13,Documents!$C$2:$C$1421,"other")),"") | U13: =IFERROR(IF(maxifs(Documents!$E$2:$E$1421,Documents!$A$2:$A$1421,$A13,Documents!$C$2:$C$1421,"obsolete")=0,"",maxifs(Documents!$E$2:$E$1421,Documents!$A$2:$A$1421,$A13,Documents!$C$2:$C$1421,"obsolete")),"") | V13: =COUNTIFS(Documents!$A$2:$A$1421,$A13) -> 19 | W13: =COUNTIFS(Documents!$A$2:$A$1421,$A13,Documents!$R$2:$R$1421,"current") -> 9 | Y13: factsheet, events
A14: 13 | B14: Sandies Bathala | C14: ok | D14: =IFERROR(IF(maxifs(Documents!$E$2:$E$1421,Documents!$A$2:$A$1421,$A14,Documents!$C$2:$C$1421,"factsheet")=0,"",maxifs(Documents!$E$2:$E$1421,Documents!$A$2:$A$1421,$A14,Documents!$C$2:$C$1421,"factsheet")),"") | E14: =IFERROR(IF(maxifs(Documents!$E$2:$E$1421,Documents!$A$2:$A$1421,$A14,Documents!$C$2:$C$1421,"wedding")=0,"",maxifs(Documents!$E$2:$E$1421,Documents!$A$2:$A$1421,$A14,Documents!$C$2:$C$1421,"wedding")),"") | F14: =IFERROR(IF(maxifs(Documents!$E$2:$E$1421,Documents!$A$2:$A$1421,$A14,Documents!$C$2:$C$1421,"events")=0,"",maxifs(Documents!$E$2:$E$1421,Documents!$A$2:$A$1421,$A14,Documents!$C$2:$C$1421,"events")),"") | G14: =IFERROR(IF(maxifs(Documents!$E$2:$E$1421,Documents!$A$2:$A$1421,$A14,Documents!$C$2:$C$1421,"map")=0,"",maxifs(Documents!$E$2:$E$1421,Documents!$A$2:$A$1421,$A14,Documents!$C$2:$C$1421,"map")),"") | H14: =IFERROR(IF(maxifs(Documents!$E$2:$E$1421,Documents!$A$2:$A$1421,$A14,Documents!$C$2:$C$1421,"dive_map")=0,"",maxifs(Documents!$E$2:$E$1421,Documents!$A$2:$A$1421,$A14,Documents!$C$2:$C$1421,"dive_map")),"") | I14: =IFERROR(IF(maxifs(Documents!$E$2:$E$1421,Documents!$A$2:$A$1421,$A14,Documents!$C$2:$C$1421,"spa_menu")=0,"",maxifs(Documents!$E$2:$E$1421,Documents!$A$2:$A$1421,$A14,Documents!$C$2:$C$1421,"spa_menu")),"") | J14: =IFERROR(IF(maxifs(Documents!$E$2:$E$1421,Documents!$A$2:$A$1421,$A14,Documents!$C$2:$C$1421,"dining_menu")=0,"",maxifs(Documents!$E$2:$E$1421,Documents!$A$2:$A$1421,$A14,Documents!$C$2:$C$1421,"dining_menu")),"") | K14: =IFERROR(IF(maxifs(Documents!$E$2:$E$1421,Documents!$A$2:$A$1421,$A14,Documents!$C$2:$C$1421,"dive_prices")=0,"",maxifs(Documents!$E$2:$E$1421,Documents!$A$2:$A$1421,$A14,Documents!$C$2:$C$1421,"dive_prices")),"") | L14: =IFERROR(IF(maxifs(Documents!$E$2:$E$1421,Documents!$A$2:$A$1421,$A14,Documents!$C$2:$C$1421,"excursions")=0,"",maxifs(Documents!$E$2:$E$1421,Documents!$A$2:$A$1421,$A14,Documents!$C$2:$C$1421,"excursions")),"") | M14: =IFERROR(IF(maxifs(Documents!$E$2:$E$1421,Documents!$A$2:$A$1421,$A14,Documents!$C$2:$C$1421,"kids")=0,"",maxifs(Documents!$E$2:$E$1421,Documents!$A$2:$A$1421,$A14,Documents!$C$2:$C$1421,"kids")),"") | N14: =IFERROR(IF(maxifs(Documents!$E$2:$E$1421,Documents!$A$2:$A$1421,$A14,Documents!$C$2:$C$1421,"villa_plans")=0,"",maxifs(Documents!$E$2:$E$1421,Documents!$A$2:$A$1421,$A14,Documents!$C$2:$C$1421,"villa_plans")),"") | O14: =IFERROR(IF(maxifs(Documents!$E$2:$E$1421,Documents!$A$2:$A$1421,$A14,Documents!$C$2:$C$1421,"all_inclusive")=0,"",maxifs(Documents!$E$2:$E$1421,Documents!$A$2:$A$1421,$A14,Documents!$C$2:$C$1421,"all_inclusive")),"") | P14: =IFERROR(IF(maxifs(Documents!$E$2:$E$1421,Documents!$A$2:$A$1421,$A14,Documents!$C$2:$C$1421,"sustainability")=0,"",maxifs(Documents!$E$2:$E$1421,Documents!$A$2:$A$1421,$A14,Documents!$C$2:$C$1421,"sustainability")),"") | Q14: =IFERROR(IF(maxifs(Documents!$E$2:$E$1421,Documents!$A$2:$A$1421,$A14,Documents!$C$2:$C$1421,"calendar")=0,"",maxifs(Documents!$E$2:$E$1421,Documents!$A$2:$A$1421,$A14,Documents!$C$2:$C$1421,"calendar")),"") | R14: =IFERROR(IF(maxifs(Documents!$E$2:$E$1421,Documents!$A$2:$A$1421,$A14,Documents!$C$2:$C$1421,"brochure")=0,"",maxifs(Documents!$E$2:$E$1421,Documents!$A$2:$A$1421,$A14,Documents!$C$2:$C$1421,"brochure")),"") | S14: =IFERROR(IF(maxifs(Documents!$E$2:$E$1421,Documents!$A$2:$A$1421,$A14,Documents!$C$2:$C$1421,"press_kit")=0,"",maxifs(Documents!$E$2:$E$1421,Documents!$A$2:$A$1421,$A14,Documents!$C$2:$C$1421,"press_kit")),"") | T14: =IFERROR(IF(maxifs(Documents!$E$2:$E$1421,Documents!$A$2:$A$1421,$A14,Documents!$C$2:$C$1421,"other")=0,"",maxifs(Documents!$E$2:$E$1421,Documents!$A$2:$A$1421,$A14,Documents!$C$2:$C$1421,"other")),"") | U14: =IFERROR(IF(maxifs(Documents!$E$2:$E$1421,Documents!$A$2:$A$1421,$A14,Documents!$C$2:$C$1421,"obsolete")=0,"",maxifs(Documents!$E$2:$E$1421,Documents!$A$2:$A$1421,$A14,Documents!$C$2:$C$1421,"obsolete")),"") | V14: =COUNTIFS(Documents!$A$2:$A$1421,$A14) -> 33 | W14: =COUNTIFS(Documents!$A$2:$A$1421,$A14,Documents!$R$2:$R$1421,"current") -> 2 | Y14: factsheet, wedding
A15: 14 | B15: Baglioni Resort Maldives | C15: blocked | D15: =IFERROR(IF(maxifs(Documents!$E$2:$E$1421,Documents!$A$2:$A$1421,$A15,Documents!$C$2:$C$1421,"factsheet")=0,"",maxifs(Documents!$E$2:$E$1421,Documents!$A$2:$A$1421,$A15,Documents!$C$2:$C$1421,"factsheet")),"") | E15: =IFERROR(IF(maxifs(Documents!$E$2:$E$1421,Documents!$A$2:$A$1421,$A15,Documents!$C$2:$C$1421,"wedding")=0,"",maxifs(Documents!$E$2:$E$1421,Documents!$A$2:$A$1421,$A15,Documents!$C$2:$C$1421,"wedding")),"") | F15: =IFERROR(IF(maxifs(Documents!$E$2:$E$1421,Documents!$A$2:$A$1421,$A15,Documents!$C$2:$C$1421,"events")=0,"",maxifs(Documents!$E$2:$E$1421,Documents!$A$2:$A$1421,$A15,Documents!$C$2:$C$1421,"events")),"") | G15: =IFERROR(IF(maxifs(Documents!$E$2:$E$1421,Documents!$A$2:$A$1421,$A15,Documents!$C$2:$C$1421,"map")=0,"",maxifs(Documents!$E$2:$E$1421,Documents!$A$2:$A$1421,$A15,Documents!$C$2:$C$1421,"map")),"") | H15: =IFERROR(IF(maxifs(Documents!$E$2:$E$1421,Documents!$A$2:$A$1421,$A15,Documents!$C$2:$C$1421,"dive_map")=0,"",maxifs(Documents!$E$2:$E$1421,Documents!$A$2:$A$1421,$A15,Documents!$C$2:$C$1421,"dive_map")),"") | I15: =IFERROR(IF(maxifs(Documents!$E$2:$E$1421,Documents!$A$2:$A$1421,$A15,Documents!$C$2:$C$1421,"spa_menu")=0,"",maxifs(Documents!$E$2:$E$1421,Documents!$A$2:$A$1421,$A15,Documents!$C$2:$C$1421,"spa_menu")),"") | J15: =IFERROR(IF(maxifs(Documents!$E$2:$E$1421,Documents!$A$2:$A$1421,$A15,Documents!$C$2:$C$1421,"dining_menu")=0,"",maxifs(Documents!$E$2:$E$1421,Documents!$A$2:$A$1421,$A15,Documents!$C$2:$C$1421,"dining_menu")),"") | K15: =IFERROR(IF(maxifs(Documents!$E$2:$E$1421,Documents!$A$2:$A$1421,$A15,Documents!$C$2:$C$1421,"dive_prices")=0,"",maxifs(Documents!$E$2:$E$1421,Documents!$A$2:$A$1421,$A15,Documents!$C$2:$C$1421,"dive_prices")),"") | L15: =IFERROR(IF(maxifs(Documents!$E$2:$E$1421,Documents!$A$2:$A$1421,$A15,Documents!$C$2:$C$1421,"excursions")=0,"",maxifs(Documents!$E$2:$E$1421,Documents!$A$2:$A$1421,$A15,Documents!$C$2:$C$1421,"excursions")),"") | M15: =IFERROR(IF(maxifs(Documents!$E$2:$E$1421,Documents!$A$2:$A$1421,$A15,Documents!$C$2:$C$1421,"kids")=0,"",maxifs(Documents!$E$2:$E$1421,Documents!$A$2:$A$1421,$A15,Documents!$C$2:$C$1421,"kids")),"") | N15: =IFERROR(IF(maxifs(Documents!$E$2:$E$1421,Documents!$A$2:$A$1421,$A15,Documents!$C$2:$C$1421,"villa_plans")=0,"",maxifs(Documents!$E$2:$E$1421,Documents!$A$2:$A$1421,$A15,Documents!$C$2:$C$1421,"villa_plans")),"") | O15: =IFERROR(IF(maxifs(Documents!$E$2:$E$1421,Documents!$A$2:$A$1421,$A15,Documents!$C$2:$C$1421,"all_inclusive")=0,"",maxifs(Documents!$E$2:$E$1421,Documents!$A$2:$A$1421,$A15,Documents!$C$2:$C$1421,"all_inclusive")),"") | P15: =IFERROR(IF(maxifs(Documents!$E$2:$E$1421,Documents!$A$2:$A$1421,$A15,Documents!$C$2:$C$1421,"sustainability")=0,"",maxifs(Documents!$E$2:$E$1421,Documents!$A$2:$A$1421,$A15,Documents!$C$2:$C$1421,"sustainability")),"") | Q15: =IFERROR(IF(maxifs(Documents!$E$2:$E$1421,Documents!$A$2:$A$1421,$A15,Documents!$C$2:$C$1421,"calendar")=0,"",maxifs(Documents!$E$2:$E$1421,Documents!$A$2:$A$1421,$A15,Documents!$C$2:$C$1421,"calendar")),"") | R15: =IFERROR(IF(maxifs(Documents!$E$2:$E$1421,Documents!$A$2:$A$1421,$A15,Documents!$C$2:$C$1421,"brochure")=0,"",maxifs(Documents!$E$2:$E$1421,Documents!$A$2:$A$1421,$A15,Documents!$C$2:$C$1421,"brochure")),"") | S15: =IFERROR(IF(maxifs(Documents!$E$2:$E$1421,Documents!$A$2:$A$1421,$A15,Documents!$C$2:$C$1421,"press_kit")=0,"",maxifs(Documents!$E$2:$E$1421,Documents!$A$2:$A$1421,$A15,Documents!$C$2:$C$1421,"press_kit")),"") | T15: =IFERROR(IF(maxifs(Documents!$E$2:$E$1421,Documents!$A$2:$A$1421,$A15,Documents!$C$2:$C$1421,"other")=0,"",maxifs(Documents!$E$2:$E$1421,Documents!$A$2:$A$1421,$A15,Documents!$C$2:$C$1421,"other")),"") | U15: =IFERROR(IF(maxifs(Documents!$E$2:$E$1421,Documents!$A$2:$A$1421,$A15,Documents!$C$2:$C$1421,"obsolete")=0,"",maxifs(Documents!$E$2:$E$1421,Documents!$A$2:$A$1421,$A15,Documents!$C$2:$C$1421,"obsolete")),"") | V15: =COUNTIFS(Documents!$A$2:$A$1421,$A15) -> 0 | W15: =COUNTIFS(Documents!$A$2:$A$1421,$A15,Documents!$R$2:$R$1421,"current") -> 0 | Y15: factsheet, wedding, events
